Workbook

Sheet Referensi
C2: Table Referensi Feeding Rate | I2: Dosis Vitamin C
I3: Pakan | J3: 1000 | K3: gram
C4: Min Berat (g) | D4: Max Berat (g) | E4: FR Min (%) | F4: FR Max (%) | I4: Vitamin C | J4: =0.0001*J3 -> 0.1 | K4: gram
C5: 1 | D5: 1 | E5: 0.01 | F5: 0.15 | G5: =AVERAGE(E5:F5) -> 0.08 | I5: Vitamin B | J5: =0.0001*J3 -> 0.1 | K5: gram
C6: 2 | D6: 5 | E6: 0.08 | F6: 0.1 | G6: =AVERAGE(E6:F6) -> 0.09 | I6: Lysin | J6: =0.003*J3 -> 3 | K6: gram
C7: 6 | D7: 20 | E7: 0.05 | F7: 0.08 | G7: =AVERAGE(E7:F7) -> 0.065 | I7: Asam Amino | J7: =0.002*J3 -> 2 | K7: gram
C8: 21 | D8: 50 | E8: 0.04 | F8: 0.05 | G8: =AVERAGE(E8:F8) -> 0.045
C9: 51 | D9: 100 | E9: 0.03 | F9: 0.04 | G9: =AVERAGE(E9:F9) -> 0.035
C10: 101 | D10: 300 | E10: 0.02 | F10: 0.03 | G10: =AVERAGE(E10:F10) -> 0.025
C11: 301 | D11: 1000 | E11: 0.01 | F11: 0.02 | G11: =AVERAGE(E11:F11) -> 0.015
J13: 500 | K13: 27
J14: 1000 | K14: 26
J15: 250 | K15: 12
J16: 350 | K16: 16
J17: =SUM(J13:J16) -> 2100 | K17: =SUM(K13:K16) -> 81
K18: =J17/K17 -> 25.925926

Sheet Konfigurasi
C4: A3 | D4: B3 | E4: C3 | F4: D3 (Heru) | G4: A6 | H4: B6 | I4: C6 | J4: D6
B5: Tipe Aerator | C5: Diffuser | D5: Uniring | E5: Diffuser | F5: Uniring | G5: Diffuser | H5: Uniring | I5: Diffuser | J5: Uniring
B6: Molase | C6: No | D6: Yes | E6: Yes | F6: No | G6: Yes | H6: Yes | I6: Yes | J6: Yes
B7: Basilus | C7: Yes | D7: Yes | E7: Yes | F7: No | G7: Yes | H7: Yes | I7: Yes | J7: Yes
B8: Kepadatan (ekor/m3) | C8: 200 | D8: 175 | E8: 175 | F8: 200 | G8: 200 | H8: 175 | I8: 175 | J8: 200
B9: Volume Air (m3) | C9: 7 | D9: 7 | E9: 7 | F9: 7 | G9: 28 | H9: 28 | I9: 28 | J9: 28
B10: Populasi (ekor) | C10: =C8*C9 -> 1400 | D10: =D8*D9 -> 1225 | E10: =E8*E9 -> 1225 | F10: =F8*F9 -> 1400 | G10: =G8*G9 -> 5600 | H10: =H8*H9 -> 4900 | I10: =I8*I9 -> 4900 | J10: =J8*J9 -> 5600
B11: Biomasa Bibit (gr/ekor) | C11: =1000/60 -> 16.666667 | D11: =1000/60 -> 16.666667 | E11: =1000/60 -> 16.666667 | F11: =1000/60 -> 16.666667 | G11: =1000/60 -> 16.666667 | H11: =1000/60 -> 16.666667 | I11: =1000/60 -> 16.666667 | J11: =1000/60 -> 16.666667
B12: Total Biomasa (gram) | C12: =C11*C10 -> 23333.333 | D12: =D11*D10 -> 20416.667 | E12: =E11*E10 -> 20416.667 | F12: =F11*F10 -> 23333.333 | G12: =G11*G10 -> 93333.333 | H12: =H11*H10 -> 81666.667 | I12: =I11*I10 -> 81666.667 | J12: =J10*J11 -> 93333.333
B13: Puasa | C13: 5:1 | D13: 5:1 | E13: 6:1 | F13: 6:1 | G13: 6:1 | H13: 6:1 | I13: 5:1 | J13: 5:1
B14: Merek Pakan | C14: Safir | D14: 781 | E14: Safir | F14: 781 | G14: 781 | H14: Safir | I14: 781 | J14: Safir
B15: Probiotik Tambahan | C15: Vit. C | D15: Vit.C + Jamu | E15: Jamu | F15: - | G15: - | H15: - | I15: - | J15: -
C18: Dosis Vitamin C
C19: 0.15 gram vitamin C / KG Pakan

Sheet Master - Pakan
B2: PENCATATAN KOLAM A | F2: Tanggal Tebar | G2: 46290 | I2: Asal Bibit | M2: Pakan
B4: Jumlah Bibit | D4: 100 | F4: Biomasa Awal | G4: =10*D4 -> 1000 | I4: Protein | J4: 0.26 | M4: Puasa
B5: Total Kematian | D5: =SUM(F13:F164) -> 0 | F5: Total Pakan | G5: =SUM(I13:I164) -> 110.5 | I5: Carbon | J5: 0.42
B6: Populasi Saat Ini | D6: =D4-D5 -> 100 | F6: Total Biomasa | G6: =IFERROR(__xludf.DUMMYFUNCTION("IFERROR(CHOOSEROWS(FILTER(H14:H162, LEN(H14:H162) > 0, H14:H162 <> 0), -1), 0)"),0.0) -> 0 | I6: Nitrogen | J6: 0.16
B7: Survival Rate (SR) | D7: =D6/D4 -> 1 | F7: FCR | G7: =IFERROR(G5/(G6-G4),0) -> -0.1105
F8: Feeding Rate | G8: =IF(G6=0,"",J8*G6) | I8: FR | J8: =IFERROR(__xludf.DUMMYFUNCTION("IFERROR(CHOOSEROWS(FILTER(D13:D161, LEN(D13:D161) > 0, D13:D161 <> 0), -1), 0)"),0.05) -> 0.05
B10: DOC | C10: Berat Rata-Rata (gr) | D10: FR (%) | F10: Kematian | G10: Populasi | H10: Biomassa (gr) | I10: Feeding Rate (gr) | J10: Pakan | L10: Molase | N10: CN Ratio | O10: Intensitas Flok | P10: PH | Q10: TDS | R10: DO | S10: Temp | T10: Actual Pakan | U10: Additional Treatment
D11: Min | E11: Max | J11: N | K11: C | L11: Berat (gr) | M11: C
A13: =G2 -> 46290 | B13: 1 | C13: 17 | D13: =IF(C13="", "", IF(VLOOKUP(C13, Referensi!$C$5:$E$11, 3, TRUE) > 1, VLOOKUP(C13, Referensi!$C$5:$E$11, 3, TRUE) / 100, VLOOKUP(C13, Referensi!$C$5:$E$11, 3, TRUE))) -> 0.05 | E13: =IF(C13="", "", IF(VLOOKUP(C13, Referensi!$C$5:$F$11, 4, TRUE) > 1, VLOOKUP(C13, Referensi!$C$5:$F$11, 4, TRUE) / 100, VLOOKUP(C13, Referensi!$C$5:$F$11, 4, TRUE))) -> 0.08 | F13: 0 | G13: =$D$4-F13 -> 100 | H13: =C13*G13 -> 1700 | I13: =IF(C13=0,"",AVERAGE(D13:E13)*H13) -> 110.5 | J13: =I13*$J$6 -> 17.68 | K13: =I13*$J$5 -> 46.41 | L13: 0 | M13: =L13*37% -> 0 | N13: =IF(J13=0,"", (K13+M13)/J13) -> 2.625
B14: 2 | C14: 0 | D14: {=_xlfn.XLOOKUP(C14,Referensi!$C$5:$C$11,Referensi!$E$5:$E$11,,-1)} | E14: {=_xlfn.XLOOKUP(C14,Referensi!$D$5:$D$11,Referensi!$F$5:$F$11,,-1)} | G14: =IF(C14="","",G13-F14) -> 100 | H14: =IF(C14="","", C14*G14) -> 0 | I14: =IF(C14=0,"",AVERAGE(D14:E14)*H14) | J14: =I14*$J$6 -> 0 | K14: =I14*$J$5 -> 0 | M14: =L14*37% -> 0 | N14: =IF(J14=0,"", (K14+M14)/J14)
B15: 3 | D15: {=_xlfn.XLOOKUP(C15,Referensi!$C$5:$C$11,Referensi!$E$5:$E$11,,-1)} | E15: {=_xlfn.XLOOKUP(C15,Referensi!$D$5:$D$11,Referensi!$F$5:$F$11,,-1)} | H15: =C15*G15 -> 0 | I15: =IF(C15=0,"",AVERAGE(D15:E15)*H15) | J15: =I15*$J$6 -> 0 | K15: =I15*$J$5 -> 0 | M15: =L15*37% -> 0 | N15: =IF(J15=0,"", (K15+M15)/J15)
B16: 4 | D16: {=_xlfn.XLOOKUP(C16,Referensi!$C$5:$C$11,Referensi!$E$5:$E$11,,-1)} | E16: {=_xlfn.XLOOKUP(C16,Referensi!$D$5:$D$11,Referensi!$F$5:$F$11,,-1)} | H16: =C16*G16 -> 0 | I16: =IF(C16=0,"",AVERAGE(D16:E16)*H16) | J16: =I16*$J$6 -> 0 | K16: =I16*$J$5 -> 0 | M16: =L16*37% -> 0 | N16: =IF(J16=0,"", (K16+M16)/J16)
B17: 5 | D17: {=_xlfn.XLOOKUP(C17,Referensi!$C$5:$C$11,Referensi!$E$5:$E$11,,-1)} | E17: {=_xlfn.XLOOKUP(C17,Referensi!$D$5:$D$11,Referensi!$F$5:$F$11,,-1)} | H17: =C17*G17 -> 0 | I17: =IF(C17=0,"",AVERAGE(D17:E17)*H17) | J17: =I17*$J$6 -> 0 | K17: =I17*$J$5 -> 0 | M17: =L17*37% -> 0 | N17: =IF(J17=0,"", (K17+M17)/J17)
B18: 6 | D18: {=_xlfn.XLOOKUP(C18,Referensi!$C$5:$C$11,Referensi!$E$5:$E$11,,-1)} | E18: {=_xlfn.XLOOKUP(C18,Referensi!$D$5:$D$11,Referensi!$F$5:$F$11,,-1)} | H18: =C18*G18 -> 0 | I18: =IF(C18=0,"",AVERAGE(D18:E18)*H18) | J18: =I18*$J$6 -> 0 | K18: =I18*$J$5 -> 0 | M18: =L18*37% -> 0 | N18: =IF(J18=0,"", (K18+M18)/J18)
B19: 7 | D19: {=_xlfn.XLOOKUP(C19,Referensi!$C$5:$C$11,Referensi!$E$5:$E$11,,-1)} | E19: {=_xlfn.XLOOKUP(C19,Referensi!$D$5:$D$11,Referensi!$F$5:$F$11,,-1)} | H19: =C19*G19 -> 0 | I19: =IF(C19=0,"",AVERAGE(D19:E19)*H19) | J19: =I19*$J$6 -> 0 | K19: =I19*$J$5 -> 0 | M19: =L19*37% -> 0 | N19: =IF(J19=0,"", (K19+M19)/J19)
B20: 8 | D20: {=_xlfn.XLOOKUP(C20,Referensi!$C$5:$C$11,Referensi!$E$5:$E$11,,-1)} | E20: {=_xlfn.XLOOKUP(C20,Referensi!$D$5:$D$11,Referensi!$F$5:$F$11,,-1)} | H20: =C20*G20 -> 0 | I20: =IF(C20=0,"",AVERAGE(D20:E20)*H20) | J20: =I20*$J$6 -> 0 | K20: =I20*$J$5 -> 0 | M20: =L20*37% -> 0 | N20: =IF(J20=0,"", (K20+M20)/J20)
B21: 9 | D21: {=_xlfn.XLOOKUP(C21,Referensi!$C$5:$C$11,Referensi!$E$5:$E$11,,-1)} | E21: {=_xlfn.XLOOKUP(C21,Referensi!$D$5:$D$11,Referensi!$F$5:$F$11,,-1)} | H21: =C21*G21 -> 0 | I21: =IF(C21=0,"",AVERAGE(D21:E21)*H21) | J21: =I21*$J$6 -> 0 | K21: =I21*$J$5 -> 0 | M21: =L21*37% -> 0 | N21: =IF(J21=0,"", (K21+M21)/J21)
B22: 10 | D22: {=_xlfn.XLOOKUP(C22,Referensi!$C$5:$C$11,Referensi!$E$5:$E$11,,-1)} | E22: {=_xlfn.XLOOKUP(C22,Referensi!$D$5:$D$11,Referensi!$F$5:$F$11,,-1)} | H22: =C22*G22 -> 0 | I22: =IF(C22=0,"",AVERAGE(D22:E22)*H22) | J22: =I22*$J$6 -> 0 | K22: =I22*$J$5 -> 0 | M22: =L22*37% -> 0 | N22: =IF(J22=0,"", (K22+M22)/J22)
B23: 11 | D23: {=_xlfn.XLOOKUP(C23,Referensi!$C$5:$C$11,Referensi!$E$5:$E$11,,-1)} | E23: {=_xlfn.XLOOKUP(C23,Referensi!$D$5:$D$11,Referensi!$F$5:$F$11,,-1)} | H23: =C23*G23 -> 0 | I23: =IF(C23=0,"",AVERAGE(D23:E23)*H23) | J23: =I23*$J$6 -> 0 | K23: =I23*$J$5 -> 0 | M23: =L23*37% -> 0 | N23: =IF(J23=0,"", (K23+M23)/J23)
B24: 12 | D24: {=_xlfn.XLOOKUP(C24,Referensi!$C$5:$C$11,Referensi!$E$5:$E$11,,-1)} | E24: {=_xlfn.XLOOKUP(C24,Referensi!$D$5:$D$11,Referensi!$F$5:$F$11,,-1)} | H24: =C24*G24 -> 0 | I24: =IF(C24=0,"",AVERAGE(D24:E24)*H24) | J24: =I24*$J$6 -> 0 | K24: =I24*$J$5 -> 0 | M24: =L24*37% -> 0 | N24: =IF(J24=0,"", (K24+M24)/J24)
B25: 13 | D25: {=_xlfn.XLOOKUP(C25,Referensi!$C$5:$C$11,Referensi!$E$5:$E$11,,-1)} | E25: {=_xlfn.XLOOKUP(C25,Referensi!$D$5:$D$11,Referensi!$F$5:$F$11,,-1)} | H25: =C25*G25 -> 0 | I25: =IF(C25=0,"",AVERAGE(D25:E25)*H25) | J25: =I25*$J$6 -> 0 | K25: =I25*$J$5 -> 0 | M25: =L25*37% -> 0 | N25: =IF(J25=0,"", (K25+M25)/J25)
B26: 14 | D26: {=_xlfn.XLOOKUP(C26,Referensi!$C$5:$C$11,Referensi!$E$5:$E$11,,-1)} | E26: {=_xlfn.XLOOKUP(C26,Referensi!$D$5:$D$11,Referensi!$F$5:$F$11,,-1)} | H26: =C26*G26 -> 0 | I26: =IF(C26=0,"",AVERAGE(D26:E26)*H26) | J26: =I26*$J$6 -> 0 | K26: =I26*$J$5 -> 0 | M26: =L26*37% -> 0 | N26: =IF(J26=0,"", (K26+M26)/J26)
... B164: 152 | D164: {=_xlfn.XLOOKUP(C164,Referensi!$C$5:$C$11,Referensi!$E$5:$E$11,,-1)} | E164: {=_xlfn.XLOOKUP(C164,Referensi!$D$5:$D$11,Referensi!$F$5:$F$11,,-1)} | H164: =C164*G164 -> 0 | I164: =IF(C164=0,"",AVERAGE(D164:E164)*H164) | J164: =I164*$J$6 -> 0 | K164: =I164*$J$5 -> 0 | M164: =L164*37% -> 0 | N164: =IF(J164=0,"", (K164+M164)/J164)

Sheet Kolam A3
B2: PENCATATAN KOLAM A3 | F2: Tanggal Tebar | G2: 20-Sept-2026 | I2: Asal Bibit | J2: Kang Ipey - Subang | M2: Pakan | N2: Safir
B4: Jumlah Bibit | D4: 1400 | F4: Biomasa Awal | G4: =C13*D4 -> 21000 | I4: Protein | J4: 0.32 | M4: Puasa | N4: 5:1
B5: Total Kematian | D5: =SUM(F13:F164) -> 231 | F5: Total Pakan | G5: =SUM(I13:I164) -> 10792.35 | I5: Carbon | J5: 0.17
B6: Populasi Saat Ini | D6: =D4-D5 -> 1169 | F6: Total Biomasa | G6: =IFERROR(__xludf.DUMMYFUNCTION("IFERROR(CHOOSEROWS(FILTER(H13:H161, LEN(H13:H161) > 0, H13:H161 <> 0), -1), ""Data Masih Kosong"")"),30325.0) -> 30325 | I6: Nitrogen | J6: 0.05 | M6: Note:
B7: Survival Rate (SR) | D7: =D6/D4 -> 0.835 | F7: FCR | G7: =IFERROR(G5/(G6-G4),0) -> 1.1573566 | M7: Tanpa Molase, gunakan gostrong & Aquacell
B8: Volume Kolam (M3) | D8: 7 | F8: Feeding Rate | G8: =IF(G6=0,"",J8*G6) -> 1213 | I8: FR | J8: =IFERROR(__xludf.DUMMYFUNCTION("IFERROR(CHOOSEROWS(FILTER(D13:D161, LEN(D13:D161) > 0, D13:D161 <> 0), -1), 0)"),0.04) -> 0.04
B10: DOC | C10: Berat Rata-Rata (gr) | D10: FR (%) | F10: Kematian | G10: Populasi | H10: Biomassa (gr) | I10: Feeding Rate (gr) | J10: Pakan | L10: Molase | N10: CN Ratio | O10: Intensitas Flok | P10: PH | Q10: TDS | R10: DO | S10: Temp | T10: Actual Pakan | U10: Additional Treatment
D11: Min | E11: Max | J11: N | K11: C | L11: Berat (gr) | M11: C
A13: 46285 | B13: 1 | C13: 15 | D13: =IF(C13="", "", IF(VLOOKUP(C13, Referensi!$C$5:$E$11, 3, TRUE) > 1, VLOOKUP(C13, Referensi!$C$5:$E$11, 3, TRUE) / 100, VLOOKUP(C13, Referensi!$C$5:$E$11, 3, TRUE))) -> 0.05 | E13: =IF(C13="", "", IF(VLOOKUP(C13, Referensi!$C$5:$F$11, 4, TRUE) > 1, VLOOKUP(C13, Referensi!$C$5:$F$11, 4, TRUE) / 100, VLOOKUP(C13, Referensi!$C$5:$F$11, 4, TRUE))) -> 0.08 | F13: 2 | G13: =$D$4-F13 -> 1398 | H13: =C13*G13 -> 20970 | I13: 0 | J13: =I13*$J$6 -> 0 | K13: =I13*$J$5 -> 0 | L13: 0 | M13: =L13*37% -> 0 | N13: =IF(J13=0,"", (K13+M13)/J13)
A14: 46286 | B14: 2 | C14: 15 | D14: =IF(C14="", "", IF(VLOOKUP(C14, Referensi!$C$5:$E$11, 3, TRUE) > 1, VLOOKUP(C14, Referensi!$C$5:$E$11, 3, TRUE) / 100, VLOOKUP(C14, Referensi!$C$5:$E$11, 3, TRUE))) -> 0.05 | E14: =IF(C14="", "", IF(VLOOKUP(C14, Referensi!$C$5:$F$11, 4, TRUE) > 1, VLOOKUP(C14, Referensi!$C$5:$F$11, 4, TRUE) / 100, VLOOKUP(C14, Referensi!$C$5:$F$11, 4, TRUE))) -> 0.08 | F14: 1 | G14: =IF(C14="","",G13-F14) -> 1397 | H14: =IF(C14="","", C14*G14) -> 20955 | I14: 0 | J14: =I14*$J$6 -> 0 | K14: =I14*$J$5 -> 0 | M14: =L14*37% -> 0 | N14: =IF(J14=0,"", (K14+M14)/J14) | P14: 7.6 | R14: 5.7 | S14: 30.4
A15: 46287 | B15: 3 | C15: 15 | D15: =IF(C15="", "", IF(VLOOKUP(C15, Referensi!$C$5:$E$11, 3, TRUE) > 1, VLOOKUP(C15, Referensi!$C$5:$E$11, 3, TRUE) / 100, VLOOKUP(C15, Referensi!$C$5:$E$11, 3, TRUE))) -> 0.05 | E15: =IF(C15="", "", IF(VLOOKUP(C15, Referensi!$C$5:$F$11, 4, TRUE) > 1, VLOOKUP(C15, Referensi!$C$5:$F$11, 4, TRUE) / 100, VLOOKUP(C15, Referensi!$C$5:$F$11, 4, TRUE))) -> 0.08 | F15: 6 | G15: =IF(C15="","",G14-F15) -> 1391 | H15: =IF(C15="","", C15*G15) -> 20865 | I15: =IF(C15=0,"",AVERAGE(D15:E15)*H15) -> 1356.225 | J15: =I15*$J$6 -> 67.81125 | K15: =I15*$J$5 -> 230.55825 | M15: =L15*37% -> 0 | N15: =IF(J15=0,"", (K15+M15)/J15) -> 3.4 | U15: Gostrong & Aquacell
A16: 46288 | B16: 4 | C16: 15 | D16: =IF(C16="", "", IF(VLOOKUP(C16, Referensi!$C$5:$E$11, 3, TRUE) > 1, VLOOKUP(C16, Referensi!$C$5:$E$11, 3, TRUE) / 100, VLOOKUP(C16, Referensi!$C$5:$E$11, 3, TRUE))) -> 0.05 | E16: =IF(C16="", "", IF(VLOOKUP(C16, Referensi!$C$5:$F$11, 4, TRUE) > 1, VLOOKUP(C16, Referensi!$C$5:$F$11, 4, TRUE) / 100, VLOOKUP(C16, Referensi!$C$5:$F$11, 4, TRUE))) -> 0.08 | F16: 9 | G16: =IF(C16="","",G15-F16) -> 1382 | H16: =IF(C16="","", C16*G16) -> 20730 | I16: =IF(C16=0,"",AVERAGE(D16:E16)*H16) -> 1347.45 | J16: =I16*$J$6 -> 67.3725 | K16: =I16*$J$5 -> 229.0665 | M16: =L16*37% -> 0 | N16: =IF(J16=0,"", (K16+M16)/J16) -> 3.4
A17: 46289 | B17: 5 | C17: 15 | D17: =IF(C17="", "", IF(VLOOKUP(C17, Referensi!$C$5:$E$11, 3, TRUE) > 1, VLOOKUP(C17, Referensi!$C$5:$E$11, 3, TRUE) / 100, VLOOKUP(C17, Referensi!$C$5:$E$11, 3, TRUE))) -> 0.05 | E17: =IF(C17="", "", IF(VLOOKUP(C17, Referensi!$C$5:$F$11, 4, TRUE) > 1, VLOOKUP(C17, Referensi!$C$5:$F$11, 4, TRUE) / 100, VLOOKUP(C17, Referensi!$C$5:$F$11, 4, TRUE))) -> 0.08 | F17: 13 | G17: =IF(C17="","",G16-F17) -> 1369 | H17: =IF(C17="","", C17*G17) -> 20535 | I17: =IF(C17=0,"",AVERAGE(D17:E17)*H17) -> 1334.775 | J17: =I17*$J$6 -> 66.73875 | K17: =I17*$J$5 -> 226.91175 | M17: =L17*37% -> 0 | N17: =IF(J17=0,"", (K17+M17)/J17) -> 3.4
A18: 46290 | B18: 6 | C18: 15 | D18: =IF(C18="", "", IF(VLOOKUP(C18, Referensi!$C$5:$E$11, 3, TRUE) > 1, VLOOKUP(C18, Referensi!$C$5:$E$11, 3, TRUE) / 100, VLOOKUP(C18, Referensi!$C$5:$E$11, 3, TRUE))) -> 0.05 | E18: =IF(C18="", "", IF(VLOOKUP(C18, Referensi!$C$5:$F$11, 4, TRUE) > 1, VLOOKUP(C18, Referensi!$C$5:$F$11, 4, TRUE) / 100, VLOOKUP(C18, Referensi!$C$5:$F$11, 4, TRUE))) -> 0.08 | F18: 19 | G18: =IF(C18="","",G17-F18) -> 1350 | H18: =IF(C18="","", C18*G18) -> 20250 | I18: =IF(C18=0,"",AVERAGE(D18:E18)*H18) -> 1316.25 | J18: =I18*$J$6 -> 65.8125 | K18: =I18*$J$5 -> 223.7625 | M18: =L18*37% -> 0 | N18: =IF(J18=0,"", (K18+M18)/J18) -> 3.4 | U18: Gostrong & Aquacell
A19: 46291 | B19: 7 | C19: 15 | D19: =IF(C19="", "", IF(VLOOKUP(C19, Referensi!$C$5:$E$11, 3, TRUE) > 1, VLOOKUP(C19, Referensi!$C$5:$E$11, 3, TRUE) / 100, VLOOKUP(C19, Referensi!$C$5:$E$11, 3, TRUE))) -> 0.05 | E19: =IF(C19="", "", IF(VLOOKUP(C19, Referensi!$C$5:$F$11, 4, TRUE) > 1, VLOOKUP(C19, Referensi!$C$5:$F$11, 4, TRUE) / 100, VLOOKUP(C19, Referensi!$C$5:$F$11, 4, TRUE))) -> 0.08 | F19: 41 | G19: =IF(C19="","",G18-F19) -> 1309 | H19: =IF(C19="","", C19*G19) -> 19635 | I19: =IF(C19=0,"",AVERAGE(D19:E19)*H19) -> 1276.275 | J19: =I19*$J$6 -> 63.81375 | K19: =I19*$J$5 -> 216.96675 | M19: =L19*37% -> 0 | N19: =IF(J19=0,"", (K19+M19)/J19) -> 3.4
A20: 46292 | B20: 8 | C20: 25 | D20: =IF(C20="", "", IF(VLOOKUP(C20, Referensi!$C$5:$E$11, 3, TRUE) > 1, VLOOKUP(C20, Referensi!$C$5:$E$11, 3, TRUE) / 100, VLOOKUP(C20, Referensi!$C$5:$E$11, 3, TRUE))) -> 0.04 | E20: =IF(C20="", "", IF(VLOOKUP(C20, Referensi!$C$5:$F$11, 4, TRUE) > 1, VLOOKUP(C20, Referensi!$C$5:$F$11, 4, TRUE) / 100, VLOOKUP(C20, Referensi!$C$5:$F$11, 4, TRUE))) -> 0.05 | F20: 26 | G20: =IF(C20="","",G19-F20) -> 1283 | H20: =IF(C20="","", C20*G20) -> 32075 | I20: 0 | J20: =I20*$J$6 -> 0 | K20: =I20*$J$5 -> 0 | M20: =L20*37% -> 0 | N20: =IF(J20=0,"", (K20+M20)/J20)
A21: 46293 | B21: 9 | C21: 25 | D21: =IF(C21="", "", IF(VLOOKUP(C21, Referensi!$C$5:$E$11, 3, TRUE) > 1, VLOOKUP(C21, Referensi!$C$5:$E$11, 3, TRUE) / 100, VLOOKUP(C21, Referensi!$C$5:$E$11, 3, TRUE))) -> 0.04 | E21: =IF(C21="", "", IF(VLOOKUP(C21, Referensi!$C$5:$F$11, 4, TRUE) > 1, VLOOKUP(C21, Referensi!$C$5:$F$11, 4, TRUE) / 100, VLOOKUP(C21, Referensi!$C$5:$F$11, 4, TRUE))) -> 0.05 | F21: 30 | G21: =IF(C21="","",G20-F21) -> 1253 | H21: =IF(C21="","", C21*G21) -> 31325 | I21: =IF(C21=0,"",AVERAGE(D21:E21)*H21) -> 1409.625 | J21: =I21*$J$6 -> 70.48125 | K21: =I21*$J$5 -> 239.63625 | M21: =L21*37% -> 0 | N21: =IF(J21=0,"", (K21+M21)/J21) -> 3.4 | U21: Gostrong & Aquacell & Vit C
A22: 46294 | B22: 10 | C22: 25 | D22: =IF(C22="", "", IF(VLOOKUP(C22, Referensi!$C$5:$E$11, 3, TRUE) > 1, VLOOKUP(C22, Referensi!$C$5:$E$11, 3, TRUE) / 100, VLOOKUP(C22, Referensi!$C$5:$E$11, 3, TRUE))) -> 0.04 | E22: =IF(C22="", "", IF(VLOOKUP(C22, Referensi!$C$5:$F$11, 4, TRUE) > 1, VLOOKUP(C22, Referensi!$C$5:$F$11, 4, TRUE) / 100, VLOOKUP(C22, Referensi!$C$5:$F$11, 4, TRUE))) -> 0.05 | F22: 20 | G22: =IF(C22="","",G21-F22) -> 1233 | H22: =IF(C22="","", C22*G22) -> 30825 | I22: =IF(C22=0,"",AVERAGE(D22:E22)*H22) -> 1387.125 | J22: =I22*$J$6 -> 69.35625 | K22: =I22*$J$5 -> 235.81125 | M22: =L22*37% -> 0 | N22: =IF(J22=0,"", (K22+M22)/J22) -> 3.4 | P22: 7.5 | R22: 4.7 | S22: 27
A23: 46295 | B23: 11 | C23: 25 | D23: =IF(C23="", "", IF(VLOOKUP(C23, Referensi!$C$5:$E$11, 3, TRUE) > 1, VLOOKUP(C23, Referensi!$C$5:$E$11, 3, TRUE) / 100, VLOOKUP(C23, Referensi!$C$5:$E$11, 3, TRUE))) -> 0.04 | E23: =IF(C23="", "", IF(VLOOKUP(C23, Referensi!$C$5:$F$11, 4, TRUE) > 1, VLOOKUP(C23, Referensi!$C$5:$F$11, 4, TRUE) / 100, VLOOKUP(C23, Referensi!$C$5:$F$11, 4, TRUE))) -> 0.05 | F23: 20 | G23: =IF(C23="","",G22-F23) -> 1213 | H23: =IF(C23="","", C23*G23) -> 30325 | I23: =IF(C23=0,"",AVERAGE(D23:E23)*H23) -> 1364.625 | J23: =I23*$J$6 -> 68.23125 | K23: =I23*$J$5 -> 231.98625 | M23: =L23*37% -> 0 | N23: =IF(J23=0,"", (K23+M23)/J23) -> 3.4
A24: 46296 | B24: 12 | D24: =IF(C24="", "", IF(VLOOKUP(C24, Referensi!$C$5:$E$11, 3, TRUE) > 1, VLOOKUP(C24, Referensi!$C$5:$E$11, 3, TRUE) / 100, VLOOKUP(C24, Referensi!$C$5:$E$11, 3, TRUE))) | E24: =IF(C24="", "", IF(VLOOKUP(C24, Referensi!$C$5:$F$11, 4, TRUE) > 1, VLOOKUP(C24, Referensi!$C$5:$F$11, 4, TRUE) / 100, VLOOKUP(C24, Referensi!$C$5:$F$11, 4, TRUE))) | F24: 18 | G24: =IF(C24="","",G23-F24) | H24: =IF(C24="","", C24*G24) | I24: =IF(C24=0,"",AVERAGE(D24:E24)*H24) | J24: =I24*$J$6 -> 0 | K24: =I24*$J$5 -> 0 | M24: =L24*37% -> 0 | N24: =IF(J24=0,"", (K24+M24)/J24) | U24: Gostrong & Aquacell
A25: 46297 | B25: 13 | D25: =IF(C25="", "", IF(VLOOKUP(C25, Referensi!$C$5:$E$11, 3, TRUE) > 1, VLOOKUP(C25, Referensi!$C$5:$E$11, 3, TRUE) / 100, VLOOKUP(C25, Referensi!$C$5:$E$11, 3, TRUE))) | E25: =IF(C25="", "", IF(VLOOKUP(C25, Referensi!$C$5:$F$11, 4, TRUE) > 1, VLOOKUP(C25, Referensi!$C$5:$F$11, 4, TRUE) / 100, VLOOKUP(C25, Referensi!$C$5:$F$11, 4, TRUE))) | F25: 26 | G25: =IF(C25="","",G24-F25) | H25: =IF(C25="","", C25*G25) | I25: =IF(C25=0,"",AVERAGE(D25:E25)*H25) | J25: =I25*$J$6 -> 0 | K25: =I25*$J$5 -> 0 | M25: =L25*37% -> 0 | N25: =IF(J25=0,"", (K25+M25)/J25)
A26: 46298 | B26: 14 | D26: =IF(C26="", "", IF(VLOOKUP(C26, Referensi!$C$5:$E$11, 3, TRUE) > 1, VLOOKUP(C26, Referensi!$C$5:$E$11, 3, TRUE) / 100, VLOOKUP(C26, Referensi!$C$5:$E$11, 3, TRUE))) | E26: =IF(C26="", "", IF(VLOOKUP(C26, Referensi!$C$5:$F$11, 4, TRUE) > 1, VLOOKUP(C26, Referensi!$C$5:$F$11, 4, TRUE) / 100, VLOOKUP(C26, Referensi!$C$5:$F$11, 4, TRUE))) | G26: =IF(C26="","",G25-F26) | H26: =IF(C26="","", C26*G26) | I26: =IF(C26=0,"",AVERAGE(D26:E26)*H26) | J26: =I26*$J$6 -> 0 | K26: =I26*$J$5 -> 0 | M26: =L26*37% -> 0 | N26: =IF(J26=0,"", (K26+M26)/J26)
A27: 46299 | B27: 15 | D27: =IF(C27="", "", IF(VLOOKUP(C27, Referensi!$C$5:$E$11, 3, TRUE) > 1, VLOOKUP(C27, Referensi!$C$5:$E$11, 3, TRUE) / 100, VLOOKUP(C27, Referensi!$C$5:$E$11, 3, TRUE))) | E27: =IF(C27="", "", IF(VLOOKUP(C27, Referensi!$C$5:$F$11, 4, TRUE) > 1, VLOOKUP(C27, Referensi!$C$5:$F$11, 4, TRUE) / 100, VLOOKUP(C27, Referensi!$C$5:$F$11, 4, TRUE))) | G27: =IF(C27="","",G26-F27) | H27: =IF(C27="","", C27*G27) | I27: =IF(C27=0,"",AVERAGE(D27:E27)*H27) | J27: =I27*$J$6 -> 0 | K27: =I27*$J$5 -> 0 | M27: =L27*37% -> 0 | N27: =IF(J27=0,"", (K27+M27)/J27) | U27: Gostrong & Aquacell
A28: 46300 | B28: 16 | D28: =IF(C28="", "", IF(VLOOKUP(C28, Referensi!$C$5:$E$11, 3, TRUE) > 1, VLOOKUP(C28, Referensi!$C$5:$E$11, 3, TRUE) / 100, VLOOKUP(C28, Referensi!$C$5:$E$11, 3, TRUE))) | E28: =IF(C28="", "", IF(VLOOKUP(C28, Referensi!$C$5:$F$11, 4, TRUE) > 1, VLOOKUP(C28, Referensi!$C$5:$F$11, 4, TRUE) / 100, VLOOKUP(C28, Referensi!$C$5:$F$11, 4, TRUE))) | G28: =IF(C28="","",G27-F28) | H28: =IF(C28="","", C28*G28) | I28: =IF(C28=0,"",AVERAGE(D28:E28)*H28) | J28: =I28*$J$6 -> 0 | K28: =I28*$J$5 -> 0 | M28: =L28*37% -> 0 | N28: =IF(J28=0,"", (K28+M28)/J28)
B29: 17 | D29: =IF(C29="", "", IF(VLOOKUP(C29, Referensi!$C$5:$E$11, 3, TRUE) > 1, VLOOKUP(C29, Referensi!$C$5:$E$11, 3, TRUE) / 100, VLOOKUP(C29, Referensi!$C$5:$E$11, 3, TRUE))) | E29: =IF(C29="", "", IF(VLOOKUP(C29, Referensi!$C$5:$F$11, 4, TRUE) > 1, VLOOKUP(C29, Referensi!$C$5:$F$11, 4, TRUE) / 100, VLOOKUP(C29, Referensi!$C$5:$F$11, 4, TRUE))) | G29: =IF(C29="","",G28-F29) | H29: =IF(C29="","", C29*G29) | I29: =IF(C29=0,"",AVERAGE(D29:E29)*H29) | J29: =I29*$J$6 -> 0 | K29: =I29*$J$5 -> 0 | M29: =L29*37% -> 0 | N29: =IF(J29=0,"", (K29+M29)/J29)
B30: 18 | D30: =IF(C30="", "", IF(VLOOKUP(C30, Referensi!$C$5:$E$11, 3, TRUE) > 1, VLOOKUP(C30, Referensi!$C$5:$E$11, 3, TRUE) / 100, VLOOKUP(C30, Referensi!$C$5:$E$11, 3, TRUE))) | E30: =IF(C30="", "", IF(VLOOKUP(C30, Referensi!$C$5:$F$11, 4, TRUE) > 1, VLOOKUP(C30, Referensi!$C$5:$F$11, 4, TRUE) / 100, VLOOKUP(C30, Referensi!$C$5:$F$11, 4, TRUE))) | G30: =IF(C30="","",G29-F30) | H30: =IF(C30="","", C30*G30) | I30: =IF(C30=0,"",AVERAGE(D30:E30)*H30) | J30: =I30*$J$6 -> 0 | K30: =I30*$J$5 -> 0 | M30: =L30*37% -> 0 | N30: =IF(J30=0,"", (K30+M30)/J30) | U30: Gostrong & Aquacell
B31: 19 | D31: =IF(C31="", "", IF(VLOOKUP(C31, Referensi!$C$5:$E$11, 3, TRUE) > 1, VLOOKUP(C31, Referensi!$C$5:$E$11, 3, TRUE) / 100, VLOOKUP(C31, Referensi!$C$5:$E$11, 3, TRUE))) | E31: =IF(C31="", "", IF(VLOOKUP(C31, Referensi!$C$5:$F$11, 4, TRUE) > 1, VLOOKUP(C31, Referensi!$C$5:$F$11, 4, TRUE) / 100, VLOOKUP(C31, Referensi!$C$5:$F$11, 4, TRUE))) | G31: =IF(C31="","",G30-F31) | H31: =IF(C31="","", C31*G31) | I31: =IF(C31=0,"",AVERAGE(D31:E31)*H31) | J31: =I31*$J$6 -> 0 | K31: =I31*$J$5 -> 0 | M31: =L31*37% -> 0 | N31: =IF(J31=0,"", (K31+M31)/J31)
B32: 20 | D32: =IF(C32="", "", IF(VLOOKUP(C32, Referensi!$C$5:$E$11, 3, TRUE) > 1, VLOOKUP(C32, Referensi!$C$5:$E$11, 3, TRUE) / 100, VLOOKUP(C32, Referensi!$C$5:$E$11, 3, TRUE))) | E32: =IF(C32="", "", IF(VLOOKUP(C32, Referensi!$C$5:$F$11, 4, TRUE) > 1, VLOOKUP(C32, Referensi!$C$5:$F$11, 4, TRUE) / 100, VLOOKUP(C32, Referensi!$C$5:$F$11, 4, TRUE))) | G32: =IF(C32="","",G31-F32) | H32: =IF(C32="","", C32*G32) | I32: =IF(C32=0,"",AVERAGE(D32:E32)*H32) | J32: =I32*$J$6 -> 0 | K32: =I32*$J$5 -> 0 | M32: =L32*37% -> 0 | N32: =IF(J32=0,"", (K32+M32)/J32)
B33: 21 | D33: =IF(C33="", "", IF(VLOOKUP(C33, Referensi!$C$5:$E$11, 3, TRUE) > 1, VLOOKUP(C33, Referensi!$C$5:$E$11, 3, TRUE) / 100, VLOOKUP(C33, Referensi!$C$5:$E$11, 3, TRUE))) | E33: =IF(C33="", "", IF(VLOOKUP(C33, Referensi!$C$5:$F$11, 4, TRUE) > 1, VLOOKUP(C33, Referensi!$C$5:$F$11, 4, TRUE) / 100, VLOOKUP(C33, Referensi!$C$5:$F$11, 4, TRUE))) | G33: =IF(C33="","",G32-F33) | H33: =IF(C33="","", C33*G33) | I33: =IF(C33=0,"",AVERAGE(D33:E33)*H33) | J33: =I33*$J$6 -> 0 | K33: =I33*$J$5 -> 0 | M33: =L33*37% -> 0 | N33: =IF(J33=0,"", (K33+M33)/J33) | U33: Gostrong & Aquacell
B34: 22 | D34: =IF(C34="", "", IF(VLOOKUP(C34, Referensi!$C$5:$E$11, 3, TRUE) > 1, VLOOKUP(C34, Referensi!$C$5:$E$11, 3, TRUE) / 100, VLOOKUP(C34, Referensi!$C$5:$E$11, 3, TRUE))) | E34: =IF(C34="", "", IF(VLOOKUP(C34, Referensi!$C$5:$F$11, 4, TRUE) > 1, VLOOKUP(C34, Referensi!$C$5:$F$11, 4, TRUE) / 100, VLOOKUP(C34, Referensi!$C$5:$F$11, 4, TRUE))) | G34: =IF(C34="","",G33-F34) | H34: =IF(C34="","", C34*G34) | I34: =IF(C34=0,"",AVERAGE(D34:E34)*H34) | J34: =I34*$J$6 -> 0 | K34: =I34*$J$5 -> 0 | M34: =L34*37% -> 0 | N34: =IF(J34=0,"", (K34+M34)/J34)
B35: 23 | D35: =IF(C35="", "", IF(VLOOKUP(C35, Referensi!$C$5:$E$11, 3, TRUE) > 1, VLOOKUP(C35, Referensi!$C$5:$E$11, 3, TRUE) / 100, VLOOKUP(C35, Referensi!$C$5:$E$11, 3, TRUE))) | E35: =IF(C35="", "", IF(VLOOKUP(C35, Referensi!$C$5:$F$11, 4, TRUE) > 1, VLOOKUP(C35, Referensi!$C$5:$F$11, 4, TRUE) / 100, VLOOKUP(C35, Referensi!$C$5:$F$11, 4, TRUE))) | G35: =IF(C35="","",G34-F35) | H35: =IF(C35="","", C35*G35) | I35: =IF(C35=0,"",AVERAGE(D35:E35)*H35) | J35: =I35*$J$6 -> 0 | K35: =I35*$J$5 -> 0 | M35: =L35*37% -> 0 | N35: =IF(J35=0,"", (K35+M35)/J35)
B36: 24 | D36: =IF(C36="", "", IF(VLOOKUP(C36, Referensi!$C$5:$E$11, 3, TRUE) > 1, VLOOKUP(C36, Referensi!$C$5:$E$11, 3, TRUE) / 100, VLOOKUP(C36, Referensi!$C$5:$E$11, 3, TRUE))) | E36: =IF(C36="", "", IF(VLOOKUP(C36, Referensi!$C$5:$F$11, 4, TRUE) > 1, VLOOKUP(C36, Referensi!$C$5:$F$11, 4, TRUE) / 100, VLOOKUP(C36, Referensi!$C$5:$F$11, 4, TRUE))) | G36: =IF(C36="","",G35-F36) | H36: =IF(C36="","", C36*G36) | I36: =IF(C36=0,"",AVERAGE(D36:E36)*H36) | J36: =I36*$J$6 -> 0 | K36: =I36*$J$5 -> 0 | M36: =L36*37% -> 0 | N36: =IF(J36=0,"", (K36+M36)/J36) | U36: Gostrong & Aquacell
B37: 25 | D37: =IF(C37="", "", IF(VLOOKUP(C37, Referensi!$C$5:$E$11, 3, TRUE) > 1, VLOOKUP(C37, Referensi!$C$5:$E$11, 3, TRUE) / 100, VLOOKUP(C37, Referensi!$C$5:$E$11, 3, TRUE))) | E37: =IF(C37="", "", IF(VLOOKUP(C37, Referensi!$C$5:$F$11, 4, TRUE) > 1, VLOOKUP(C37, Referensi!$C$5:$F$11, 4, TRUE) / 100, VLOOKUP(C37, Referensi!$C$5:$F$11, 4, TRUE))) | G37: =IF(C37="","",G36-F37) | H37: =IF(C37="","", C37*G37) | I37: =IF(C37=0,"",AVERAGE(D37:E37)*H37) | J37: =I37*$J$6 -> 0 | K37: =I37*$J$5 -> 0 | M37: =L37*37% -> 0 | N37: =IF(J37=0,"", (K37+M37)/J37)
B38: 26 | D38: =IF(C38="", "", IF(VLOOKUP(C38, Referensi!$C$5:$E$11, 3, TRUE) > 1, VLOOKUP(C38, Referensi!$C$5:$E$11, 3, TRUE) / 100, VLOOKUP(C38, Referensi!$C$5:$E$11, 3, TRUE))) | E38: =IF(C38="", "", IF(VLOOKUP(C38, Referensi!$C$5:$F$11, 4, TRUE) > 1, VLOOKUP(C38, Referensi!$C$5:$F$11, 4, TRUE) / 100, VLOOKUP(C38, Referensi!$C$5:$F$11, 4, TRUE))) | G38: =IF(C38="","",G37-F38) | H38: =IF(C38="","", C38*G38) | I38: =IF(C38=0,"",AVERAGE(D38:E38)*H38) | J38: =I38*$J$6 -> 0 | K38: =I38*$J$5 -> 0 | M38: =L38*37% -> 0 | N38: =IF(J38=0,"", (K38+M38)/J38)
B39: 27 | D39: =IF(C39="", "", IF(VLOOKUP(C39, Referensi!$C$5:$E$11, 3, TRUE) > 1, VLOOKUP(C39, Referensi!$C$5:$E$11, 3, TRUE) / 100, VLOOKUP(C39, Referensi!$C$5:$E$11, 3, TRUE))) | E39: =IF(C39="", "", IF(VLOOKUP(C39, Referensi!$C$5:$F$11, 4, TRUE) > 1, VLOOKUP(C39, Referensi!$C$5:$F$11, 4, TRUE) / 100, VLOOKUP(C39, Referensi!$C$5:$F$11, 4, TRUE))) | G39: =IF(C39="","",G38-F39) | H39: =IF(C39="","", C39*G39) | I39: =IF(C39=0,"",AVERAGE(D39:E39)*H39) | J39: =I39*$J$6 -> 0 | K39: =I39*$J$5 -> 0 | M39: =L39*37% -> 0 | N39: =IF(J39=0,"", (K39+M39)/J39) | U39: Gostrong & Aquacell
B40: 28 | D40: =IF(C40="", "", IF(VLOOKUP(C40, Referensi!$C$5:$E$11, 3, TRUE) > 1, VLOOKUP(C40, Referensi!$C$5:$E$11, 3, TRUE) / 100, VLOOKUP(C40, Referensi!$C$5:$E$11, 3, TRUE))) | E40: =IF(C40="", "", IF(VLOOKUP(C40, Referensi!$C$5:$F$11, 4, TRUE) > 1, VLOOKUP(C40, Referensi!$C$5:$F$11, 4, TRUE) / 100, VLOOKUP(C40, Referensi!$C$5:$F$11, 4, TRUE))) | G40: =IF(C40="","",G39-F40) | H40: =IF(C40="","", C40*G40) | I40: =IF(C40=0,"",AVERAGE(D40:E40)*H40) | J40: =I40*$J$6 -> 0 | K40: =I40*$J$5 -> 0 | M40: =L40*37% -> 0 | N40: =IF(J40=0,"", (K40+M40)/J40)
B41: 29 | D41: =IF(C41="", "", IF(VLOOKUP(C41, Referensi!$C$5:$E$11, 3, TRUE) > 1, VLOOKUP(C41, Referensi!$C$5:$E$11, 3, TRUE) / 100, VLOOKUP(C41, Referensi!$C$5:$E$11, 3, TRUE))) | E41: =IF(C41="", "", IF(VLOOKUP(C41, Referensi!$C$5:$F$11, 4, TRUE) > 1, VLOOKUP(C41, Referensi!$C$5:$F$11, 4, TRUE) / 100, VLOOKUP(C41, Referensi!$C$5:$F$11, 4, TRUE))) | G41: =IF(C41="","",G40-F41) | H41: =IF(C41="","", C41*G41) | I41: =IF(C41=0,"",AVERAGE(D41:E41)*H41) | J41: =I41*$J$6 -> 0 | K41: =I41*$J$5 -> 0 | M41: =L41*37% -> 0 | N41: =IF(J41=0,"", (K41+M41)/J41)
B42: 30 | D42: =IF(C42="", "", IF(VLOOKUP(C42, Referensi!$C$5:$E$11, 3, TRUE) > 1, VLOOKUP(C42, Referensi!$C$5:$E$11, 3, TRUE) / 100, VLOOKUP(C42, Referensi!$C$5:$E$11, 3, TRUE))) | E42: =IF(C42="", "", IF(VLOOKUP(C42, Referensi!$C$5:$F$11, 4, TRUE) > 1, VLOOKUP(C42, Referensi!$C$5:$F$11, 4, TRUE) / 100, VLOOKUP(C42, Referensi!$C$5:$F$11, 4, TRUE))) | G42: =IF(C42="","",G41-F42) | H42: =IF(C42="","", C42*G42) | I42: =IF(C42=0,"",AVERAGE(D42:E42)*H42) | J42: =I42*$J$6 -> 0 | K42: =I42*$J$5 -> 0 | M42: =L42*37% -> 0 | N42: =IF(J42=0,"", (K42+M42)/J42) | U42: Gostrong & Aquacell
B43: 31 | D43: =IF(C43="", "", IF(VLOOKUP(C43, Referensi!$C$5:$E$11, 3, TRUE) > 1, VLOOKUP(C43, Referensi!$C$5:$E$11, 3, TRUE) / 100, VLOOKUP(C43, Referensi!$C$5:$E$11, 3, TRUE))) | E43: =IF(C43="", "", IF(VLOOKUP(C43, Referensi!$C$5:$F$11, 4, TRUE) > 1, VLOOKUP(C43, Referensi!$C$5:$F$11, 4, TRUE) / 100, VLOOKUP(C43, Referensi!$C$5:$F$11, 4, TRUE))) | G43: =IF(C43="","",G42-F43) | H43: =IF(C43="","", C43*G43) | I43: =IF(C43=0,"",AVERAGE(D43:E43)*H43) | J43: =I43*$J$6 -> 0 | K43: =I43*$J$5 -> 0 | M43: =L43*37% -> 0 | N43: =IF(J43=0,"", (K43+M43)/J43)
B44: 32 | D44: =IF(C44="", "", IF(VLOOKUP(C44, Referensi!$C$5:$E$11, 3, TRUE) > 1, VLOOKUP(C44, Referensi!$C$5:$E$11, 3, TRUE) / 100, VLOOKUP(C44, Referensi!$C$5:$E$11, 3, TRUE))) | E44: =IF(C44="", "", IF(VLOOKUP(C44, Referensi!$C$5:$F$11, 4, TRUE) > 1, VLOOKUP(C44, Referensi!$C$5:$F$11, 4, TRUE) / 100, VLOOKUP(C44, Referensi!$C$5:$F$11, 4, TRUE))) | G44: =IF(C44="","",G43-F44) | H44: =IF(C44="","", C44*G44) | I44: =IF(C44=0,"",AVERAGE(D44:E44)*H44) | J44: =I44*$J$6 -> 0 | K44: =I44*$J$5 -> 0 | M44: =L44*37% -> 0 | N44: =IF(J44=0,"", (K44+M44)/J44)
...

Sheet Kolam B3
B2: PENCATATAN KOLAM B3 | F2: Tanggal Tebar | G2: 46290 | I2: Asal Bibit | J2: Kang Ipey - Subang | M2: Pakan | N2: 781
B4: Jumlah Bibit | D4: 1225 | F4: Biomasa Awal | G4: =C13*D4 -> 8575 | I4: Protein | J4: 0.32 | M4: Puasa | N4: 5:1
B5: Total Kematian | D5: =SUM(F13:F164) -> 91 | F5: Total Pakan | G5: =SUM(I13:I164) -> 2525.965 | I5: Carbon | J5: 0.35
B6: Populasi Saat Ini | D6: =D4-D5 -> 1134 | F6: Total Biomasa | G6: =IFERROR(__xludf.DUMMYFUNCTION("IFERROR(CHOOSEROWS(FILTER(H13:H161, LEN(H13:H161) > 0, H13:H161 <> 0), -1), ""Data Masih Kosong"")"),6822.0) -> 6822 | I6: Nitrogen | J6: 0.05
B7: Survival Rate (SR) | D7: =D6/D4 -> 0.92571429 | F7: FCR | G7: =IFERROR(G5/(G6-G4),0) -> -1.4409384
B8: Volume Kolam (M3) | D8: 7 | F8: Feeding Rate | G8: =IF(G6=0,"",J8*G6) -> 341.1 | I8: FR | J8: =IFERROR(__xludf.DUMMYFUNCTION("IFERROR(CHOOSEROWS(FILTER(D13:D161, LEN(D13:D161) > 0, D13:D161 <> 0), -1), 0)"),0.05) -> 0.05
B10: DOC | C10: Berat Rata-Rata (gr) | D10: FR (%) | F10: Kematian | G10: Populasi | H10: Biomassa (gr) | I10: Feeding Rate (gr) | J10: Pakan | L10: Molase | N10: CN Ratio | O10: Intensitas Flok | P10: PH | Q10: TDS | R10: DO | S10: Temp | T10: Actual Pakan | U10: Additional Treatment
D11: Min | E11: Max | J11: N | K11: C | L11: Berat (gr) | M11: C
A13: 46290 | B13: 1 | C13: 7 | D13: =IF(C13="", "", IF(VLOOKUP(C13, Referensi!$C$5:$E$11, 3, TRUE) > 1, VLOOKUP(C13, Referensi!$C$5:$E$11, 3, TRUE) / 100, VLOOKUP(C13, Referensi!$C$5:$E$11, 3, TRUE))) -> 0.05 | E13: =IF(C13="", "", IF(VLOOKUP(C13, Referensi!$C$5:$F$11, 4, TRUE) > 1, VLOOKUP(C13, Referensi!$C$5:$F$11, 4, TRUE) / 100, VLOOKUP(C13, Referensi!$C$5:$F$11, 4, TRUE))) -> 0.08 | F13: 0 | G13: =$D$4-F13 -> 1225 | H13: =C13*G13 -> 8575 | I13: 0 | J13: =I13*$J$6 -> 0 | K13: =I13*$J$5 -> 0 | L13: 0 | M13: =L13*37% -> 0 | N13: =IF(J13=0,"", (K13+M13)/J13)
A14: 46291 | B14: 2 | C14: 7 | D14: =IF(C14="", "", IF(VLOOKUP(C14, Referensi!$C$5:$E$11, 3, TRUE) > 1, VLOOKUP(C14, Referensi!$C$5:$E$11, 3, TRUE) / 100, VLOOKUP(C14, Referensi!$C$5:$E$11, 3, TRUE))) -> 0.05 | E14: =IF(C14="", "", IF(VLOOKUP(C14, Referensi!$C$5:$F$11, 4, TRUE) > 1, VLOOKUP(C14, Referensi!$C$5:$F$11, 4, TRUE) / 100, VLOOKUP(C14, Referensi!$C$5:$F$11, 4, TRUE))) -> 0.08 | F14: 11 | G14: =IF(C14="","",G13-F14) -> 1214 | H14: =IF(C14="","", C14*G14) -> 8498 | I14: 0 | J14: =I14*$J$6 -> 0 | K14: =I14*$J$5 -> 0 | M14: =L14*37% -> 0 | N14: =IF(J14=0,"", (K14+M14)/J14) | P14: 8.77 | R14: 5.9 | S14: 31.1
A15: 46292 | B15: 3 | C15: 7 | D15: =IF(C15="", "", IF(VLOOKUP(C15, Referensi!$C$5:$E$11, 3, TRUE) > 1, VLOOKUP(C15, Referensi!$C$5:$E$11, 3, TRUE) / 100, VLOOKUP(C15, Referensi!$C$5:$E$11, 3, TRUE))) -> 0.05 | E15: =IF(C15="", "", IF(VLOOKUP(C15, Referensi!$C$5:$F$11, 4, TRUE) > 1, VLOOKUP(C15, Referensi!$C$5:$F$11, 4, TRUE) / 100, VLOOKUP(C15, Referensi!$C$5:$F$11, 4, TRUE))) -> 0.08 | F15: 3 | G15: =IF(C15="","",G14-F15) -> 1211 | H15: =IF(C15="","", C15*G15) -> 8477 | I15: =IF(C15=0,"",AVERAGE(D15:E15)*H15) -> 551.005 | J15: =I15*$J$6 -> 27.55025 | K15: =I15*$J$5 -> 192.85175 | M15: =L15*37% -> 0 | N15: =IF(J15=0,"", (K15+M15)/J15) -> 7
A16: 46293 | B16: 4 | C16: 7 | D16: =IF(C16="", "", IF(VLOOKUP(C16, Referensi!$C$5:$E$11, 3, TRUE) > 1, VLOOKUP(C16, Referensi!$C$5:$E$11, 3, TRUE) / 100, VLOOKUP(C16, Referensi!$C$5:$E$11, 3, TRUE))) -> 0.05 | E16: =IF(C16="", "", IF(VLOOKUP(C16, Referensi!$C$5:$F$11, 4, TRUE) > 1, VLOOKUP(C16, Referensi!$C$5:$F$11, 4, TRUE) / 100, VLOOKUP(C16, Referensi!$C$5:$F$11, 4, TRUE))) -> 0.08 | F16: 12 | G16: =IF(C16="","",G15-F16) -> 1199 | H16: =IF(C16="","", C16*G16) -> 8393 | I16: =IF(C16=0,"",AVERAGE(D16:E16)*H16) -> 545.545 | J16: =I16*$J$6 -> 27.27725 | K16: =I16*$J$5 -> 190.94075 | M16: =L16*37% -> 0 | N16: =IF(J16=0,"", (K16+M16)/J16) -> 7
A17: 46294 | B17: 5 | C17: 7 | D17: =IF(C17="", "", IF(VLOOKUP(C17, Referensi!$C$5:$E$11, 3, TRUE) > 1, VLOOKUP(C17, Referensi!$C$5:$E$11, 3, TRUE) / 100, VLOOKUP(C17, Referensi!$C$5:$E$11, 3, TRUE))) -> 0.05 | E17: =IF(C17="", "", IF(VLOOKUP(C17, Referensi!$C$5:$F$11, 4, TRUE) > 1, VLOOKUP(C17, Referensi!$C$5:$F$11, 4, TRUE) / 100, VLOOKUP(C17, Referensi!$C$5:$F$11, 4, TRUE))) -> 0.08 | F17: 22 | G17: =IF(C17="","",G16-F17) -> 1177 | H17: =IF(C17="","", C17*G17) -> 8239 | I17: =IF(C17=0,"",AVERAGE(D17:E17)*H17) -> 535.535 | J17: =I17*$J$6 -> 26.77675 | K17: =I17*$J$5 -> 187.43725 | M17: =L17*37% -> 0 | N17: =IF(J17=0,"", (K17+M17)/J17) -> 7 | P17: 7.6 | R17: 6.6 | S17: 28 | U17: Basilus
A18: 46295 | B18: 6 | C18: 6 | D18: =IF(C18="", "", IF(VLOOKUP(C18, Referensi!$C$5:$E$11, 3, TRUE) > 1, VLOOKUP(C18, Referensi!$C$5:$E$11, 3, TRUE) / 100, VLOOKUP(C18, Referensi!$C$5:$E$11, 3, TRUE))) -> 0.05 | E18: =IF(C18="", "", IF(VLOOKUP(C18, Referensi!$C$5:$F$11, 4, TRUE) > 1, VLOOKUP(C18, Referensi!$C$5:$F$11, 4, TRUE) / 100, VLOOKUP(C18, Referensi!$C$5:$F$11, 4, TRUE))) -> 0.08 | F18: 22 | G18: =IF(C18="","",G17-F18) -> 1155 | H18: =IF(C18="","", C18*G18) -> 6930 | I18: =IF(C18=0,"",AVERAGE(D18:E18)*H18) -> 450.45 | J18: =I18*$J$6 -> 22.5225 | K18: =I18*$J$5 -> 157.6575 | M18: =L18*37% -> 0 | N18: =IF(J18=0,"", (K18+M18)/J18) -> 7 | U18: Gostrong + Aquacell
A19: 46296 | B19: 7 | C19: 6 | D19: =IF(C19="", "", IF(VLOOKUP(C19, Referensi!$C$5:$E$11, 3, TRUE) > 1, VLOOKUP(C19, Referensi!$C$5:$E$11, 3, TRUE) / 100, VLOOKUP(C19, Referensi!$C$5:$E$11, 3, TRUE))) -> 0.05 | E19: =IF(C19="", "", IF(VLOOKUP(C19, Referensi!$C$5:$F$11, 4, TRUE) > 1, VLOOKUP(C19, Referensi!$C$5:$F$11, 4, TRUE) / 100, VLOOKUP(C19, Referensi!$C$5:$F$11, 4, TRUE))) -> 0.08 | F19: 18 | G19: =IF(C19="","",G18-F19) -> 1137 | H19: =IF(C19="","", C19*G19) -> 6822 | I19: =IF(C19=0,"",AVERAGE(D19:E19)*H19) -> 443.43 | J19: =I19*$J$6 -> 22.1715 | K19: =I19*$J$5 -> 155.2005 | M19: =L19*37% -> 0 | N19: =IF(J19=0,"", (K19+M19)/J19) -> 7 | T19: =654-38 -> 616
A20: 46297 | B20: 8 | D20: =IF(C20="", "", IF(VLOOKUP(C20, Referensi!$C$5:$E$11, 3, TRUE) > 1, VLOOKUP(C20, Referensi!$C$5:$E$11, 3, TRUE) / 100, VLOOKUP(C20, Referensi!$C$5:$E$11, 3, TRUE))) | E20: =IF(C20="", "", IF(VLOOKUP(C20, Referensi!$C$5:$F$11, 4, TRUE) > 1, VLOOKUP(C20, Referensi!$C$5:$F$11, 4, TRUE) / 100, VLOOKUP(C20, Referensi!$C$5:$F$11, 4, TRUE))) | F20: 3 | G20: =IF(C20="","",G19-F20) | H20: =IF(C20="","", C20*G20) | I20: =IF(C20=0,"",AVERAGE(D20:E20)*H20) | J20: =I20*$J$6 -> 0 | K20: =I20*$J$5 -> 0 | M20: =L20*37% -> 0 | N20: =IF(J20=0,"", (K20+M20)/J20)
A21: 46298 | B21: 9 | D21: =IF(C21="", "", IF(VLOOKUP(C21, Referensi!$C$5:$E$11, 3, TRUE) > 1, VLOOKUP(C21, Referensi!$C$5:$E$11, 3, TRUE) / 100, VLOOKUP(C21, Referensi!$C$5:$E$11, 3, TRUE))) | E21: =IF(C21="", "", IF(VLOOKUP(C21, Referensi!$C$5:$F$11, 4, TRUE) > 1, VLOOKUP(C21, Referensi!$C$5:$F$11, 4, TRUE) / 100, VLOOKUP(C21, Referensi!$C$5:$F$11, 4, TRUE))) | G21: =IF(C21="","",G20-F21) | H21: =IF(C21="","", C21*G21) | I21: =IF(C21=0,"",AVERAGE(D21:E21)*H21) | J21: =I21*$J$6 -> 0 | K21: =I21*$J$5 -> 0 | M21: =L21*37% -> 0 | N21: =IF(J21=0,"", (K21+M21)/J21)
A22: 46299 | B22: 10 | D22: =IF(C22="", "", IF(VLOOKUP(C22, Referensi!$C$5:$E$11, 3, TRUE) > 1, VLOOKUP(C22, Referensi!$C$5:$E$11, 3, TRUE) / 100, VLOOKUP(C22, Referensi!$C$5:$E$11, 3, TRUE))) | E22: =IF(C22="", "", IF(VLOOKUP(C22, Referensi!$C$5:$F$11, 4, TRUE) > 1, VLOOKUP(C22, Referensi!$C$5:$F$11, 4, TRUE) / 100, VLOOKUP(C22, Referensi!$C$5:$F$11, 4, TRUE))) | G22: =IF(C22="","",G21-F22) | H22: =IF(C22="","", C22*G22) | I22: =IF(C22=0,"",AVERAGE(D22:E22)*H22) | J22: =I22*$J$6 -> 0 | K22: =I22*$J$5 -> 0 | M22: =L22*37% -> 0 | N22: =IF(J22=0,"", (K22+M22)/J22)
A23: 46300 | B23: 11 | D23: =IF(C23="", "", IF(VLOOKUP(C23, Referensi!$C$5:$E$11, 3, TRUE) > 1, VLOOKUP(C23, Referensi!$C$5:$E$11, 3, TRUE) / 100, VLOOKUP(C23, Referensi!$C$5:$E$11, 3, TRUE))) | E23: =IF(C23="", "", IF(VLOOKUP(C23, Referensi!$C$5:$F$11, 4, TRUE) > 1, VLOOKUP(C23, Referensi!$C$5:$F$11, 4, TRUE) / 100, VLOOKUP(C23, Referensi!$C$5:$F$11, 4, TRUE))) | G23: =IF(C23="","",G22-F23) | H23: =IF(C23="","", C23*G23) | I23: =IF(C23=0,"",AVERAGE(D23:E23)*H23) | J23: =I23*$J$6 -> 0 | K23: =I23*$J$5 -> 0 | M23: =L23*37% -> 0 | N23: =IF(J23=0,"", (K23+M23)/J23)
A24: 46301 | B24: 12 | D24: =IF(C24="", "", IF(VLOOKUP(C24, Referensi!$C$5:$E$11, 3, TRUE) > 1, VLOOKUP(C24, Referensi!$C$5:$E$11, 3, TRUE) / 100, VLOOKUP(C24, Referensi!$C$5:$E$11, 3, TRUE))) | E24: =IF(C24="", "", IF(VLOOKUP(C24, Referensi!$C$5:$F$11, 4, TRUE) > 1, VLOOKUP(C24, Referensi!$C$5:$F$11, 4, TRUE) / 100, VLOOKUP(C24, Referensi!$C$5:$F$11, 4, TRUE))) | G24: =IF(C24="","",G23-F24) | H24: =IF(C24="","", C24*G24) | I24: =IF(C24=0,"",AVERAGE(D24:E24)*H24) | J24: =I24*$J$6 -> 0 | K24: =I24*$J$5 -> 0 | M24: =L24*37% -> 0 | N24: =IF(J24=0,"", (K24+M24)/J24)
A25: 46302 | B25: 13 | D25: =IF(C25="", "", IF(VLOOKUP(C25, Referensi!$C$5:$E$11, 3, TRUE) > 1, VLOOKUP(C25, Referensi!$C$5:$E$11, 3, TRUE) / 100, VLOOKUP(C25, Referensi!$C$5:$E$11, 3, TRUE))) | E25: =IF(C25="", "", IF(VLOOKUP(C25, Referensi!$C$5:$F$11, 4, TRUE) > 1, VLOOKUP(C25, Referensi!$C$5:$F$11, 4, TRUE) / 100, VLOOKUP(C25, Referensi!$C$5:$F$11, 4, TRUE))) | G25: =IF(C25="","",G24-F25) | H25: =IF(C25="","", C25*G25) | I25: =IF(C25=0,"",AVERAGE(D25:E25)*H25) | J25: =I25*$J$6 -> 0 | K25: =I25*$J$5 -> 0 | M25: =L25*37% -> 0 | N25: =IF(J25=0,"", (K25+M25)/J25)
A26: 46303 | B26: 14 | D26: =IF(C26="", "", IF(VLOOKUP(C26, Referensi!$C$5:$E$11, 3, TRUE) > 1, VLOOKUP(C26, Referensi!$C$5:$E$11, 3, TRUE) / 100, VLOOKUP(C26, Referensi!$C$5:$E$11, 3, TRUE))) | E26: =IF(C26="", "", IF(VLOOKUP(C26, Referensi!$C$5:$F$11, 4, TRUE) > 1, VLOOKUP(C26, Referensi!$C$5:$F$11, 4, TRUE) / 100, VLOOKUP(C26, Referensi!$C$5:$F$11, 4, TRUE))) | G26: =IF(C26="","",G25-F26) | H26: =IF(C26="","", C26*G26) | I26: =IF(C26=0,"",AVERAGE(D26:E26)*H26) | J26: =I26*$J$6 -> 0 | K26: =I26*$J$5 -> 0 | M26: =L26*37% -> 0 | N26: =IF(J26=0,"", (K26+M26)/J26)
B27: 15 | D27: =IF(C27="", "", IF(VLOOKUP(C27, Referensi!$C$5:$E$11, 3, TRUE) > 1, VLOOKUP(C27, Referensi!$C$5:$E$11, 3, TRUE) / 100, VLOOKUP(C27, Referensi!$C$5:$E$11, 3, TRUE))) | E27: =IF(C27="", "", IF(VLOOKUP(C27, Referensi!$C$5:$F$11, 4, TRUE) > 1, VLOOKUP(C27, Referensi!$C$5:$F$11, 4, TRUE) / 100, VLOOKUP(C27, Referensi!$C$5:$F$11, 4, TRUE))) | G27: =IF(C27="","",G26-F27) | H27: =IF(C27="","", C27*G27) | I27: =IF(C27=0,"",AVERAGE(D27:E27)*H27) | J27: =I27*$J$6 -> 0 | K27: =I27*$J$5 -> 0 | M27: =L27*37% -> 0 | N27: =IF(J27=0,"", (K27+M27)/J27)
B28: 16 | D28: =IF(C28="", "", IF(VLOOKUP(C28, Referensi!$C$5:$E$11, 3, TRUE) > 1, VLOOKUP(C28, Referensi!$C$5:$E$11, 3, TRUE) / 100, VLOOKUP(C28, Referensi!$C$5:$E$11, 3, TRUE))) | E28: =IF(C28="", "", IF(VLOOKUP(C28, Referensi!$C$5:$F$11, 4, TRUE) > 1, VLOOKUP(C28, Referensi!$C$5:$F$11, 4, TRUE) / 100, VLOOKUP(C28, Referensi!$C$5:$F$11, 4, TRUE))) | G28: =IF(C28="","",G27-F28) | H28: =IF(C28="","", C28*G28) | I28: =IF(C28=0,"",AVERAGE(D28:E28)*H28) | J28: =I28*$J$6 -> 0 | K28: =I28*$J$5 -> 0 | M28: =L28*37% -> 0 | N28: =IF(J28=0,"", (K28+M28)/J28)
B29: 17 | D29: =IF(C29="", "", IF(VLOOKUP(C29, Referensi!$C$5:$E$11, 3, TRUE) > 1, VLOOKUP(C29, Referensi!$C$5:$E$11, 3, TRUE) / 100, VLOOKUP(C29, Referensi!$C$5:$E$11, 3, TRUE))) | E29: =IF(C29="", "", IF(VLOOKUP(C29, Referensi!$C$5:$F$11, 4, TRUE) > 1, VLOOKUP(C29, Referensi!$C$5:$F$11, 4, TRUE) / 100, VLOOKUP(C29, Referensi!$C$5:$F$11, 4, TRUE))) | G29: =IF(C29="","",G28-F29) | H29: =IF(C29="","", C29*G29) | I29: =IF(C29=0,"",AVERAGE(D29:E29)*H29) | J29: =I29*$J$6 -> 0 | K29: =I29*$J$5 -> 0 | M29: =L29*37% -> 0 | N29: =IF(J29=0,"", (K29+M29)/J29)
B30: 18 | D30: =IF(C30="", "", IF(VLOOKUP(C30, Referensi!$C$5:$E$11, 3, TRUE) > 1, VLOOKUP(C30, Referensi!$C$5:$E$11, 3, TRUE) / 100, VLOOKUP(C30, Referensi!$C$5:$E$11, 3, TRUE))) | E30: =IF(C30="", "", IF(VLOOKUP(C30, Referensi!$C$5:$F$11, 4, TRUE) > 1, VLOOKUP(C30, Referensi!$C$5:$F$11, 4, TRUE) / 100, VLOOKUP(C30, Referensi!$C$5:$F$11, 4, TRUE))) | G30: =IF(C30="","",G29-F30) | H30: =IF(C30="","", C30*G30) | I30: =IF(C30=0,"",AVERAGE(D30:E30)*H30) | J30: =I30*$J$6 -> 0 | K30: =I30*$J$5 -> 0 | M30: =L30*37% -> 0 | N30: =IF(J30=0,"", (K30+M30)/J30)
B31: 19 | D31: =IF(C31="", "", IF(VLOOKUP(C31, Referensi!$C$5:$E$11, 3, TRUE) > 1, VLOOKUP(C31, Referensi!$C$5:$E$11, 3, TRUE) / 100, VLOOKUP(C31, Referensi!$C$5:$E$11, 3, TRUE))) | E31: =IF(C31="", "", IF(VLOOKUP(C31, Referensi!$C$5:$F$11, 4, TRUE) > 1, VLOOKUP(C31, Referensi!$C$5:$F$11, 4, TRUE) / 100, VLOOKUP(C31, Referensi!$C$5:$F$11, 4, TRUE))) | G31: =IF(C31="","",G30-F31) | H31: =IF(C31="","", C31*G31) | I31: =IF(C31=0,"",AVERAGE(D31:E31)*H31) | J31: =I31*$J$6 -> 0 | K31: =I31*$J$5 -> 0 | M31: =L31*37% -> 0 | N31: =IF(J31=0,"", (K31+M31)/J31)
B32: 20 | D32: =IF(C32="", "", IF(VLOOKUP(C32, Referensi!$C$5:$E$11, 3, TRUE) > 1, VLOOKUP(C32, Referensi!$C$5:$E$11, 3, TRUE) / 100, VLOOKUP(C32, Referensi!$C$5:$E$11, 3, TRUE))) | E32: =IF(C32="", "", IF(VLOOKUP(C32, Referensi!$C$5:$F$11, 4, TRUE) > 1, VLOOKUP(C32, Referensi!$C$5:$F$11, 4, TRUE) / 100, VLOOKUP(C32, Referensi!$C$5:$F$11, 4, TRUE))) | G32: =IF(C32="","",G31-F32) | H32: =IF(C32="","", C32*G32) | I32: =IF(C32=0,"",AVERAGE(D32:E32)*H32) | J32: =I32*$J$6 -> 0 | K32: =I32*$J$5 -> 0 | M32: =L32*37% -> 0 | N32: =IF(J32=0,"", (K32+M32)/J32)
B33: 21 | D33: =IF(C33="", "", IF(VLOOKUP(C33, Referensi!$C$5:$E$11, 3, TRUE) > 1, VLOOKUP(C33, Referensi!$C$5:$E$11, 3, TRUE) / 100, VLOOKUP(C33, Referensi!$C$5:$E$11, 3, TRUE))) | E33: =IF(C33="", "", IF(VLOOKUP(C33, Referensi!$C$5:$F$11, 4, TRUE) > 1, VLOOKUP(C33, Referensi!$C$5:$F$11, 4, TRUE) / 100, VLOOKUP(C33, Referensi!$C$5:$F$11, 4, TRUE))) | G33: =IF(C33="","",G32-F33) | H33: =IF(C33="","", C33*G33) | I33: =IF(C33=0,"",AVERAGE(D33:E33)*H33) | J33: =I33*$J$6 -> 0 | K33: =I33*$J$5 -> 0 | M33: =L33*37% -> 0 | N33: =IF(J33=0,"", (K33+M33)/J33)
B34: 22 | D34: =IF(C34="", "", IF(VLOOKUP(C34, Referensi!$C$5:$E$11, 3, TRUE) > 1, VLOOKUP(C34, Referensi!$C$5:$E$11, 3, TRUE) / 100, VLOOKUP(C34, Referensi!$C$5:$E$11, 3, TRUE))) | E34: =IF(C34="", "", IF(VLOOKUP(C34, Referensi!$C$5:$F$11, 4, TRUE) > 1, VLOOKUP(C34, Referensi!$C$5:$F$11, 4, TRUE) / 100, VLOOKUP(C34, Referensi!$C$5:$F$11, 4, TRUE))) | G34: =IF(C34="","",G33-F34) | H34: =IF(C34="","", C34*G34) | I34: =IF(C34=0,"",AVERAGE(D34:E34)*H34) | J34: =I34*$J$6 -> 0 | K34: =I34*$J$5 -> 0 | M34: =L34*37% -> 0 | N34: =IF(J34=0,"", (K34+M34)/J34)
B35: 23 | D35: =IF(C35="", "", IF(VLOOKUP(C35, Referensi!$C$5:$E$11, 3, TRUE) > 1, VLOOKUP(C35, Referensi!$C$5:$E$11, 3, TRUE) / 100, VLOOKUP(C35, Referensi!$C$5:$E$11, 3, TRUE))) | E35: =IF(C35="", "", IF(VLOOKUP(C35, Referensi!$C$5:$F$11, 4, TRUE) > 1, VLOOKUP(C35, Referensi!$C$5:$F$11, 4, TRUE) / 100, VLOOKUP(C35, Referensi!$C$5:$F$11, 4, TRUE))) | G35: =IF(C35="","",G34-F35) | H35: =IF(C35="","", C35*G35) | I35: =IF(C35=0,"",AVERAGE(D35:E35)*H35) | J35: =I35*$J$6 -> 0 | K35: =I35*$J$5 -> 0 | M35: =L35*37% -> 0 | N35: =IF(J35=0,"", (K35+M35)/J35)
B36: 24 | D36: =IF(C36="", "", IF(VLOOKUP(C36, Referensi!$C$5:$E$11, 3, TRUE) > 1, VLOOKUP(C36, Referensi!$C$5:$E$11, 3, TRUE) / 100, VLOOKUP(C36, Referensi!$C$5:$E$11, 3, TRUE))) | E36: =IF(C36="", "", IF(VLOOKUP(C36, Referensi!$C$5:$F$11, 4, TRUE) > 1, VLOOKUP(C36, Referensi!$C$5:$F$11, 4, TRUE) / 100, VLOOKUP(C36, Referensi!$C$5:$F$11, 4, TRUE))) | G36: =IF(C36="","",G35-F36) | H36: =IF(C36="","", C36*G36) | I36: =IF(C36=0,"",AVERAGE(D36:E36)*H36) | J36: =I36*$J$6 -> 0 | K36: =I36*$J$5 -> 0 | M36: =L36*37% -> 0 | N36: =IF(J36=0,"", (K36+M36)/J36)
B37: 25 | D37: =IF(C37="", "", IF(VLOOKUP(C37, Referensi!$C$5:$E$11, 3, TRUE) > 1, VLOOKUP(C37, Referensi!$C$5:$E$11, 3, TRUE) / 100, VLOOKUP(C37, Referensi!$C$5:$E$11, 3, TRUE))) | E37: =IF(C37="", "", IF(VLOOKUP(C37, Referensi!$C$5:$F$11, 4, TRUE) > 1, VLOOKUP(C37, Referensi!$C$5:$F$11, 4, TRUE) / 100, VLOOKUP(C37, Referensi!$C$5:$F$11, 4, TRUE))) | G37: =IF(C37="","",G36-F37) | H37: =IF(C37="","", C37*G37) | I37: =IF(C37=0,"",AVERAGE(D37:E37)*H37) | J37: =I37*$J$6 -> 0 | K37: =I37*$J$5 -> 0 | M37: =L37*37% -> 0 | N37: =IF(J37=0,"", (K37+M37)/J37)
B38: 26 | D38: =IF(C38="", "", IF(VLOOKUP(C38, Referensi!$C$5:$E$11, 3, TRUE) > 1, VLOOKUP(C38, Referensi!$C$5:$E$11, 3, TRUE) / 100, VLOOKUP(C38, Referensi!$C$5:$E$11, 3, TRUE))) | E38: =IF(C38="", "", IF(VLOOKUP(C38, Referensi!$C$5:$F$11, 4, TRUE) > 1, VLOOKUP(C38, Referensi!$C$5:$F$11, 4, TRUE) / 100, VLOOKUP(C38, Referensi!$C$5:$F$11, 4, TRUE))) | G38: =IF(C38="","",G37-F38) | H38: =IF(C38="","", C38*G38) | I38: =IF(C38=0,"",AVERAGE(D38:E38)*H38) | J38: =I38*$J$6 -> 0 | K38: =I38*$J$5 -> 0 | M38: =L38*37% -> 0 | N38: =IF(J38=0,"", (K38+M38)/J38)
... B164: 152 | D164: =IF(C164="", "", IF(VLOOKUP(C164, Referensi!$C$5:$E$11, 3, TRUE) > 1, VLOOKUP(C164, Referensi!$C$5:$E$11, 3, TRUE) / 100, VLOOKUP(C164, Referensi!$C$5:$E$11, 3, TRUE))) | E164: =IF(C164="", "", IF(VLOOKUP(C164, Referensi!$C$5:$F$11, 4, TRUE) > 1, VLOOKUP(C164, Referensi!$C$5:$F$11, 4, TRUE) / 100, VLOOKUP(C164, Referensi!$C$5:$F$11, 4, TRUE))) | G164: =IF(C164="","",G163-F164) | H164: =IF(C164="","", C164*G164) | I164: =IF(C164=0,"",AVERAGE(D164:E164)*H164) | J164: =I164*$J$6 -> 0 | K164: =I164*$J$5 -> 0 | M164: =L164*37% -> 0 | N164: =IF(J164=0,"", (K164+M164)/J164)

Sheet Kolam C3
B2: PENCATATAN KOLAM C3 | F2: Tanggal Tebar | G2: 24-Sept-2026 | I2: Asal Bibit | J2: Cibinong | M2: Pakan | N2: Safir
B4: Jumlah Bibit | D4: 1225 | F4: Biomasa Awal | G4: =C13*D4 -> 8575 | I4: Protein | J4: 0.32 | M4: Puasa | N4: 6:1
B5: Total Kematian | D5: =SUM(F13:F164) -> 248 | F5: Total Pakan | G5: =SUM(I13:I164) -> 2860.895 | I5: Carbon | J5: 0.17
B6: Populasi Saat Ini | D6: =D4-D5 -> 977 | F6: Total Biomasa | G6: =IFERROR(__xludf.DUMMYFUNCTION("IFERROR(CHOOSEROWS(FILTER(H13:H161, LEN(H13:H161) > 0, H13:H161 <> 0), -1), ""Data Masih Kosong"")"),5055.0) -> 5055 | I6: Nitrogen | J6: 0.05
B7: Survival Rate (SR) | D7: =D6/D4 -> 0.79755102 | F7: FCR | G7: =IFERROR(G5/(G6-G4),0) -> -0.81275426
B8: Volume Kolam (M3) | D8: 7 | F8: Feeding Rate | G8: =IF(G6=0,"",J8*G6) -> 404.4 | I8: FR | J8: =IFERROR(__xludf.DUMMYFUNCTION("IFERROR(CHOOSEROWS(FILTER(D13:D161, LEN(D13:D161) > 0, D13:D161 <> 0), -1), 0)"),0.08) -> 0.08
B10: DOC | C10: Berat Rata-Rata (gr) | D10: FR (%) | F10: Kematian | G10: Populasi | H10: Biomassa (gr) | I10: Feeding Rate (gr) | J10: Pakan | L10: Molase | N10: CN Ratio | O10: Intensitas Flok | P10: PH | Q10: TDS | R10: DO | S10: Temp | T10: Actual Pakan | U10: Additional Treatment
D11: Min | E11: Max | J11: N | K11: C | L11: Berat (gr) | M11: C
A13: 46289 | B13: 1 | C13: 7 | D13: =IF(C13="", "", IF(VLOOKUP(C13, Referensi!$C$5:$E$11, 3, TRUE) > 1, VLOOKUP(C13, Referensi!$C$5:$E$11, 3, TRUE) / 100, VLOOKUP(C13, Referensi!$C$5:$E$11, 3, TRUE))) -> 0.05 | E13: =IF(C13="", "", IF(VLOOKUP(C13, Referensi!$C$5:$F$11, 4, TRUE) > 1, VLOOKUP(C13, Referensi!$C$5:$F$11, 4, TRUE) / 100, VLOOKUP(C13, Referensi!$C$5:$F$11, 4, TRUE))) -> 0.08 | F13: 24 | G13: =$D$4-F13 -> 1201 | H13: =C13*G13 -> 8407 | I13: 0 | J13: =I13*$J$6 -> 0 | K13: =I13*$J$5 -> 0 | L13: 0 | M13: =L13*37% -> 0 | N13: =IF(J13=0,"", (K13+M13)/J13)
A14: 46290 | B14: 2 | C14: 7 | D14: =IF(C14="", "", IF(VLOOKUP(C14, Referensi!$C$5:$E$11, 3, TRUE) > 1, VLOOKUP(C14, Referensi!$C$5:$E$11, 3, TRUE) / 100, VLOOKUP(C14, Referensi!$C$5:$E$11, 3, TRUE))) -> 0.05 | E14: =IF(C14="", "", IF(VLOOKUP(C14, Referensi!$C$5:$F$11, 4, TRUE) > 1, VLOOKUP(C14, Referensi!$C$5:$F$11, 4, TRUE) / 100, VLOOKUP(C14, Referensi!$C$5:$F$11, 4, TRUE))) -> 0.08 | F14: 44 | G14: =IF(C14="","",G13-F14) -> 1157 | H14: =IF(C14="","", C14*G14) -> 8099 | I14: 0 | J14: =I14*$J$6 -> 0 | K14: =I14*$J$5 -> 0 | M14: =L14*37% -> 0 | N14: =IF(J14=0,"", (K14+M14)/J14) | P14: 8.6 | Q14: 6.3 | R14: 30.9
A15: 46291 | B15: 3 | C15: 7 | D15: =IF(C15="", "", IF(VLOOKUP(C15, Referensi!$C$5:$E$11, 3, TRUE) > 1, VLOOKUP(C15, Referensi!$C$5:$E$11, 3, TRUE) / 100, VLOOKUP(C15, Referensi!$C$5:$E$11, 3, TRUE))) -> 0.05 | E15: =IF(C15="", "", IF(VLOOKUP(C15, Referensi!$C$5:$F$11, 4, TRUE) > 1, VLOOKUP(C15, Referensi!$C$5:$F$11, 4, TRUE) / 100, VLOOKUP(C15, Referensi!$C$5:$F$11, 4, TRUE))) -> 0.08 | F15: 38 | G15: =IF(C15="","",G14-F15) -> 1119 | H15: =IF(C15="","", C15*G15) -> 7833 | I15: =IF(C15=0,"",AVERAGE(D15:E15)*H15) -> 509.145 | J15: =I15*$J$6 -> 25.45725 | K15: =I15*$J$5 -> 86.55465 | M15: =L15*37% -> 0 | N15: =IF(J15=0,"", (K15+M15)/J15) -> 3.4
A16: 46292 | B16: 4 | C16: 7 | D16: =IF(C16="", "", IF(VLOOKUP(C16, Referensi!$C$5:$E$11, 3, TRUE) > 1, VLOOKUP(C16, Referensi!$C$5:$E$11, 3, TRUE) / 100, VLOOKUP(C16, Referensi!$C$5:$E$11, 3, TRUE))) -> 0.05 | E16: =IF(C16="", "", IF(VLOOKUP(C16, Referensi!$C$5:$F$11, 4, TRUE) > 1, VLOOKUP(C16, Referensi!$C$5:$F$11, 4, TRUE) / 100, VLOOKUP(C16, Referensi!$C$5:$F$11, 4, TRUE))) -> 0.08 | F16: 34 | G16: =IF(C16="","",G15-F16) -> 1085 | H16: =IF(C16="","", C16*G16) -> 7595 | I16: =IF(C16=0,"",AVERAGE(D16:E16)*H16) -> 493.675 | J16: =I16*$J$6 -> 24.68375 | K16: =I16*$J$5 -> 83.92475 | M16: =L16*37% -> 0 | N16: =IF(J16=0,"", (K16+M16)/J16) -> 3.4
A17: 46293 | B17: 5 | C17: 7 | D17: =IF(C17="", "", IF(VLOOKUP(C17, Referensi!$C$5:$E$11, 3, TRUE) > 1, VLOOKUP(C17, Referensi!$C$5:$E$11, 3, TRUE) / 100, VLOOKUP(C17, Referensi!$C$5:$E$11, 3, TRUE))) -> 0.05 | E17: =IF(C17="", "", IF(VLOOKUP(C17, Referensi!$C$5:$F$11, 4, TRUE) > 1, VLOOKUP(C17, Referensi!$C$5:$F$11, 4, TRUE) / 100, VLOOKUP(C17, Referensi!$C$5:$F$11, 4, TRUE))) -> 0.08 | F17: 45 | G17: =IF(C17="","",G16-F17) -> 1040 | H17: =IF(C17="","", C17*G17) -> 7280 | I17: =IF(C17=0,"",AVERAGE(D17:E17)*H17) -> 473.2 | J17: =I17*$J$6 -> 23.66 | K17: =I17*$J$5 -> 80.444 | M17: =L17*37% -> 0 | N17: =IF(J17=0,"", (K17+M17)/J17) -> 3.4
A18: 46294 | B18: 6 | C18: 7 | D18: =IF(C18="", "", IF(VLOOKUP(C18, Referensi!$C$5:$E$11, 3, TRUE) > 1, VLOOKUP(C18, Referensi!$C$5:$E$11, 3, TRUE) / 100, VLOOKUP(C18, Referensi!$C$5:$E$11, 3, TRUE))) -> 0.05 | E18: =IF(C18="", "", IF(VLOOKUP(C18, Referensi!$C$5:$F$11, 4, TRUE) > 1, VLOOKUP(C18, Referensi!$C$5:$F$11, 4, TRUE) / 100, VLOOKUP(C18, Referensi!$C$5:$F$11, 4, TRUE))) -> 0.08 | F18: 5 | G18: =IF(C18="","",G17-F18) -> 1035 | H18: =IF(C18="","", C18*G18) -> 7245 | I18: =IF(C18=0,"",AVERAGE(D18:E18)*H18) -> 470.925 | J18: =I18*$J$6 -> 23.54625 | K18: =I18*$J$5 -> 80.05725 | M18: =L18*37% -> 0 | N18: =IF(J18=0,"", (K18+M18)/J18) -> 3.4 | P18: 7.5 | R18: 5.4 | S18: 30
A19: 46295 | B19: 7 | C19: 5 | D19: =IF(C19="", "", IF(VLOOKUP(C19, Referensi!$C$5:$E$11, 3, TRUE) > 1, VLOOKUP(C19, Referensi!$C$5:$E$11, 3, TRUE) / 100, VLOOKUP(C19, Referensi!$C$5:$E$11, 3, TRUE))) -> 0.08 | E19: =IF(C19="", "", IF(VLOOKUP(C19, Referensi!$C$5:$F$11, 4, TRUE) > 1, VLOOKUP(C19, Referensi!$C$5:$F$11, 4, TRUE) / 100, VLOOKUP(C19, Referensi!$C$5:$F$11, 4, TRUE))) -> 0.1 | F19: 15 | G19: =IF(C19="","",G18-F19) -> 1020 | H19: =IF(C19="","", C19*G19) -> 5100 | I19: =IF(C19=0,"",AVERAGE(D19:E19)*H19) -> 459 | J19: =I19*$J$6 -> 22.95 | K19: =I19*$J$5 -> 78.03 | M19: =L19*37% -> 0 | N19: =IF(J19=0,"", (K19+M19)/J19) -> 3.4
A20: 46296 | B20: 8 | C20: 5 | D20: =IF(C20="", "", IF(VLOOKUP(C20, Referensi!$C$5:$E$11, 3, TRUE) > 1, VLOOKUP(C20, Referensi!$C$5:$E$11, 3, TRUE) / 100, VLOOKUP(C20, Referensi!$C$5:$E$11, 3, TRUE))) -> 0.08 | E20: =IF(C20="", "", IF(VLOOKUP(C20, Referensi!$C$5:$F$11, 4, TRUE) > 1, VLOOKUP(C20, Referensi!$C$5:$F$11, 4, TRUE) / 100, VLOOKUP(C20, Referensi!$C$5:$F$11, 4, TRUE))) -> 0.1 | F20: 9 | G20: =IF(C20="","",G19-F20) -> 1011 | H20: =IF(C20="","", C20*G20) -> 5055 | I20: =IF(C20=0,"",AVERAGE(D20:E20)*H20) -> 454.95 | J20: =I20*$J$6 -> 22.7475 | K20: =I20*$J$5 -> 77.3415 | M20: =L20*37% -> 0 | N20: =IF(J20=0,"", (K20+M20)/J20) -> 3.4 | T20: =370-50 -> 320
A21: 46297 | B21: 9 | D21: =IF(C21="", "", IF(VLOOKUP(C21, Referensi!$C$5:$E$11, 3, TRUE) > 1, VLOOKUP(C21, Referensi!$C$5:$E$11, 3, TRUE) / 100, VLOOKUP(C21, Referensi!$C$5:$E$11, 3, TRUE))) | E21: =IF(C21="", "", IF(VLOOKUP(C21, Referensi!$C$5:$F$11, 4, TRUE) > 1, VLOOKUP(C21, Referensi!$C$5:$F$11, 4, TRUE) / 100, VLOOKUP(C21, Referensi!$C$5:$F$11, 4, TRUE))) | F21: 34 | G21: =IF(C21="","",G20-F21) | H21: =IF(C21="","", C21*G21) | I21: =IF(C21=0,"",AVERAGE(D21:E21)*H21) | J21: =I21*$J$6 -> 0 | K21: =I21*$J$5 -> 0 | M21: =L21*37% -> 0 | N21: =IF(J21=0,"", (K21+M21)/J21)
A22: 46298 | B22: 10 | D22: =IF(C22="", "", IF(VLOOKUP(C22, Referensi!$C$5:$E$11, 3, TRUE) > 1, VLOOKUP(C22, Referensi!$C$5:$E$11, 3, TRUE) / 100, VLOOKUP(C22, Referensi!$C$5:$E$11, 3, TRUE))) | E22: =IF(C22="", "", IF(VLOOKUP(C22, Referensi!$C$5:$F$11, 4, TRUE) > 1, VLOOKUP(C22, Referensi!$C$5:$F$11, 4, TRUE) / 100, VLOOKUP(C22, Referensi!$C$5:$F$11, 4, TRUE))) | G22: =IF(C22="","",G21-F22) | H22: =IF(C22="","", C22*G22) | I22: =IF(C22=0,"",AVERAGE(D22:E22)*H22) | J22: =I22*$J$6 -> 0 | K22: =I22*$J$5 -> 0 | M22: =L22*37% -> 0 | N22: =IF(J22=0,"", (K22+M22)/J22)
A23: 46299 | B23: 11 | D23: =IF(C23="", "", IF(VLOOKUP(C23, Referensi!$C$5:$E$11, 3, TRUE) > 1, VLOOKUP(C23, Referensi!$C$5:$E$11, 3, TRUE) / 100, VLOOKUP(C23, Referensi!$C$5:$E$11, 3, TRUE))) | E23: =IF(C23="", "", IF(VLOOKUP(C23, Referensi!$C$5:$F$11, 4, TRUE) > 1, VLOOKUP(C23, Referensi!$C$5:$F$11, 4, TRUE) / 100, VLOOKUP(C23, Referensi!$C$5:$F$11, 4, TRUE))) | G23: =IF(C23="","",G22-F23) | H23: =IF(C23="","", C23*G23) | I23: =IF(C23=0,"",AVERAGE(D23:E23)*H23) | J23: =I23*$J$6 -> 0 | K23: =I23*$J$5 -> 0 | M23: =L23*37% -> 0 | N23: =IF(J23=0,"", (K23+M23)/J23)
A24: 46300 | B24: 12 | D24: =IF(C24="", "", IF(VLOOKUP(C24, Referensi!$C$5:$E$11, 3, TRUE) > 1, VLOOKUP(C24, Referensi!$C$5:$E$11, 3, TRUE) / 100, VLOOKUP(C24, Referensi!$C$5:$E$11, 3, TRUE))) | E24: =IF(C24="", "", IF(VLOOKUP(C24, Referensi!$C$5:$F$11, 4, TRUE) > 1, VLOOKUP(C24, Referensi!$C$5:$F$11, 4, TRUE) / 100, VLOOKUP(C24, Referensi!$C$5:$F$11, 4, TRUE))) | G24: =IF(C24="","",G23-F24) | H24: =IF(C24="","", C24*G24) | I24: =IF(C24=0,"",AVERAGE(D24:E24)*H24) | J24: =I24*$J$6 -> 0 | K24: =I24*$J$5 -> 0 | M24: =L24*37% -> 0 | N24: =IF(J24=0,"", (K24+M24)/J24)
A25: 46301 | B25: 13 | D25: =IF(C25="", "", IF(VLOOKUP(C25, Referensi!$C$5:$E$11, 3, TRUE) > 1, VLOOKUP(C25, Referensi!$C$5:$E$11, 3, TRUE) / 100, VLOOKUP(C25, Referensi!$C$5:$E$11, 3, TRUE))) | E25: =IF(C25="", "", IF(VLOOKUP(C25, Referensi!$C$5:$F$11, 4, TRUE) > 1, VLOOKUP(C25, Referensi!$C$5:$F$11, 4, TRUE) / 100, VLOOKUP(C25, Referensi!$C$5:$F$11, 4, TRUE))) | G25: =IF(C25="","",G24-F25) | H25: =IF(C25="","", C25*G25) | I25: =IF(C25=0,"",AVERAGE(D25:E25)*H25) | J25: =I25*$J$6 -> 0 | K25: =I25*$J$5 -> 0 | M25: =L25*37% -> 0 | N25: =IF(J25=0,"", (K25+M25)/J25)
A26: 46302 | B26: 14 | D26: =IF(C26="", "", IF(VLOOKUP(C26, Referensi!$C$5:$E$11, 3, TRUE) > 1, VLOOKUP(C26, Referensi!$C$5:$E$11, 3, TRUE) / 100, VLOOKUP(C26, Referensi!$C$5:$E$11, 3, TRUE))) | E26: =IF(C26="", "", IF(VLOOKUP(C26, Referensi!$C$5:$F$11, 4, TRUE) > 1, VLOOKUP(C26, Referensi!$C$5:$F$11, 4, TRUE) / 100, VLOOKUP(C26, Referensi!$C$5:$F$11, 4, TRUE))) | G26: =IF(C26="","",G25-F26) | H26: =IF(C26="","", C26*G26) | I26: =IF(C26=0,"",AVERAGE(D26:E26)*H26) | J26: =I26*$J$6 -> 0 | K26: =I26*$J$5 -> 0 | M26: =L26*37% -> 0 | N26: =IF(J26=0,"", (K26+M26)/J26)
B27: 15 | D27: =IF(C27="", "", IF(VLOOKUP(C27, Referensi!$C$5:$E$11, 3, TRUE) > 1, VLOOKUP(C27, Referensi!$C$5:$E$11, 3, TRUE) / 100, VLOOKUP(C27, Referensi!$C$5:$E$11, 3, TRUE))) | E27: =IF(C27="", "", IF(VLOOKUP(C27, Referensi!$C$5:$F$11, 4, TRUE) > 1, VLOOKUP(C27, Referensi!$C$5:$F$11, 4, TRUE) / 100, VLOOKUP(C27, Referensi!$C$5:$F$11, 4, TRUE))) | G27: =IF(C27="","",G26-F27) | H27: =IF(C27="","", C27*G27) | I27: =IF(C27=0,"",AVERAGE(D27:E27)*H27) | J27: =I27*$J$6 -> 0 | K27: =I27*$J$5 -> 0 | M27: =L27*37% -> 0 | N27: =IF(J27=0,"", (K27+M27)/J27)
B28: 16 | D28: =IF(C28="", "", IF(VLOOKUP(C28, Referensi!$C$5:$E$11, 3, TRUE) > 1, VLOOKUP(C28, Referensi!$C$5:$E$11, 3, TRUE) / 100, VLOOKUP(C28, Referensi!$C$5:$E$11, 3, TRUE))) | E28: =IF(C28="", "", IF(VLOOKUP(C28, Referensi!$C$5:$F$11, 4, TRUE) > 1, VLOOKUP(C28, Referensi!$C$5:$F$11, 4, TRUE) / 100, VLOOKUP(C28, Referensi!$C$5:$F$11, 4, TRUE))) | G28: =IF(C28="","",G27-F28) | H28: =IF(C28="","", C28*G28) | I28: =IF(C28=0,"",AVERAGE(D28:E28)*H28) | J28: =I28*$J$6 -> 0 | K28: =I28*$J$5 -> 0 | M28: =L28*37% -> 0 | N28: =IF(J28=0,"", (K28+M28)/J28)
B29: 17 | D29: =IF(C29="", "", IF(VLOOKUP(C29, Referensi!$C$5:$E$11, 3, TRUE) > 1, VLOOKUP(C29, Referensi!$C$5:$E$11, 3, TRUE) / 100, VLOOKUP(C29, Referensi!$C$5:$E$11, 3, TRUE))) | E29: =IF(C29="", "", IF(VLOOKUP(C29, Referensi!$C$5:$F$11, 4, TRUE) > 1, VLOOKUP(C29, Referensi!$C$5:$F$11, 4, TRUE) / 100, VLOOKUP(C29, Referensi!$C$5:$F$11, 4, TRUE))) | G29: =IF(C29="","",G28-F29) | H29: =IF(C29="","", C29*G29) | I29: =IF(C29=0,"",AVERAGE(D29:E29)*H29) | J29: =I29*$J$6 -> 0 | K29: =I29*$J$5 -> 0 | M29: =L29*37% -> 0 | N29: =IF(J29=0,"", (K29+M29)/J29)
B30: 18 | D30: =IF(C30="", "", IF(VLOOKUP(C30, Referensi!$C$5:$E$11, 3, TRUE) > 1, VLOOKUP(C30, Referensi!$C$5:$E$11, 3, TRUE) / 100, VLOOKUP(C30, Referensi!$C$5:$E$11, 3, TRUE))) | E30: =IF(C30="", "", IF(VLOOKUP(C30, Referensi!$C$5:$F$11, 4, TRUE) > 1, VLOOKUP(C30, Referensi!$C$5:$F$11, 4, TRUE) / 100, VLOOKUP(C30, Referensi!$C$5:$F$11, 4, TRUE))) | G30: =IF(C30="","",G29-F30) | H30: =IF(C30="","", C30*G30) | I30: =IF(C30=0,"",AVERAGE(D30:E30)*H30) | J30: =I30*$J$6 -> 0 | K30: =I30*$J$5 -> 0 | M30: =L30*37% -> 0 | N30: =IF(J30=0,"", (K30+M30)/J30)
B31: 19 | D31: =IF(C31="", "", IF(VLOOKUP(C31, Referensi!$C$5:$E$11, 3, TRUE) > 1, VLOOKUP(C31, Referensi!$C$5:$E$11, 3, TRUE) / 100, VLOOKUP(C31, Referensi!$C$5:$E$11, 3, TRUE))) | E31: =IF(C31="", "", IF(VLOOKUP(C31, Referensi!$C$5:$F$11, 4, TRUE) > 1, VLOOKUP(C31, Referensi!$C$5:$F$11, 4, TRUE) / 100, VLOOKUP(C31, Referensi!$C$5:$F$11, 4, TRUE))) | G31: =IF(C31="","",G30-F31) | H31: =IF(C31="","", C31*G31) | I31: =IF(C31=0,"",AVERAGE(D31:E31)*H31) | J31: =I31*$J$6 -> 0 | K31: =I31*$J$5 -> 0 | M31: =L31*37% -> 0 | N31: =IF(J31=0,"", (K31+M31)/J31)
B32: 20 | D32: =IF(C32="", "", IF(VLOOKUP(C32, Referensi!$C$5:$E$11, 3, TRUE) > 1, VLOOKUP(C32, Referensi!$C$5:$E$11, 3, TRUE) / 100, VLOOKUP(C32, Referensi!$C$5:$E$11, 3, TRUE))) | E32: =IF(C32="", "", IF(VLOOKUP(C32, Referensi!$C$5:$F$11, 4, TRUE) > 1, VLOOKUP(C32, Referensi!$C$5:$F$11, 4, TRUE) / 100, VLOOKUP(C32, Referensi!$C$5:$F$11, 4, TRUE))) | G32: =IF(C32="","",G31-F32) | H32: =IF(C32="","", C32*G32) | I32: =IF(C32=0,"",AVERAGE(D32:E32)*H32) | J32: =I32*$J$6 -> 0 | K32: =I32*$J$5 -> 0 | M32: =L32*37% -> 0 | N32: =IF(J32=0,"", (K32+M32)/J32)
